Workbook

Sheet MIN
A1: ORDENES DE COMPRA MINERÍA
A2: CÓDIGO | B2: CLIENTES | C2: Nº Orden | D2: PROYECTO | E2: FECHA O/C | F2: FECHA ENTREGA | G2: VALOR PRESUPUESTO $ | H2: COSTO | I2: HH Propia | J2: IMPREVISTOS | K2: UTILIDAD | L2: Personal | N2: Empresa | O2: Monto O/C | P2: Cantidad
A3: 222023A-ANGQ-P | B3: ANGLO AMERICAN QUELLAVECO S.A. | C3: 2MAY3279-CON-0001_05 | D3: 2.MAY.3279 Mantenimiento de Redes de Comunicación Industrial, Componentes del Sistema de Control y Sistema de Monitoreo de Condición | E3: 46008 | F3: 45908 | G3: 521378.4 | H3: 228130.1 | I3: 237615 | J3: 0 | K3: 55633.3 | L3: Eduardo | N3: ANGLO AMERICAN QUELLAVECO S.A. | O3: =SUMIF(B:B,"ANGLO AMERICAN QUELLAVECO S.A.",G:G) | P3: =COUNTIF(B:B,"ANGLO AMERICAN QUELLAVECO S.A.")
A4: 262003A-PREP-S | B4: Precision Peru SA | C4: 5000 | D4: Servicio de técnicos perfil eléctrico. | E4: 46020 | F4: 46047 | G4: 1992.68 | H4: 734 | I4: 1092 | J4: 0 | K4: 166.68 | L4: Eduardo | N4: Compañía Minera Poderosa SA | O4: =SUMIF(B:B,"Compañía Minera Poderosa SA",G:G) | P4: =COUNTIF(B:B,"Compañía Minera Poderosa SA")
A5: 262010A-PREP-V | B5: Precision Peru SA | C5: 5064 | D5: Equipo de protección personal - adicional | E5: 46034 | F5: 46034 | G5: 164.4881 | H5: 164.4881 | I5: 0 | J5: 0 | K5: 0 | L5: Eduardo | N5: MARCOBRE S.A.C. | O5: =SUMIF(B:B,"MARCOBRE S.A.C.",G:G) | P5: =COUNTIF(B:B,"MARCOBRE S.A.C.")
A6: 262016B-SHA-V | B6: SHAHUINDO S.A.C. | C6: 49857 | D6: LUMINARIA MODELO SOLARIS SOLICITUD 177391 | E6: 46048 | F6: 46108 | G6: 29680 | H6: 26500 | I6: 0 | J6: 0 | K6: 3180 | L6: Eduardo | N6: MINERA LAS BAMBAS S.A. | O6: =SUMIF(B:B,"MINERA LAS BAMBAS S.A.",G:G) | P6: =COUNTIF(B:B,"MINERA LAS BAMBAS S.A.")
A7: 262028A-MMG-V | B7: MINERA LAS BAMBAS S.A. | C7: 4400669247 | D7: Solicitud de cotización S1045572 | E7: 46051 | F7: 46114 | G7: 1787.49 | H7: 1191.66 | I7: 0 | J7: 0 | K7: 595.83 | L7: Eduardo | N7: MINERA YANACOCHA | O7: =SUMIF(B:B,"MINERA YANACOCHA",G:G) | P7: =COUNTIF(B:B,"MINERA YANACOCHA")
A8: 262022A-SPCC-V | B8: SOUTHERN PERU COPPER CORPORATION | C8: 4100790414 | D8: Licitación 3000545027 ST VARIOS ELÉCTRICOS | E8: 46055 | F8: 46124 | G8: 12783.94 | H8: 11161.28 | I8: 0 | J8: 0 | K8: 1622.66 | L8: Eduardo | N8: Precision Peru SA | O8: =SUMIF(B:B,"Precision Peru SA",G:G) | P8: =COUNTIF(B:B,"Precision Peru SA")
A9: 262009B-SPCC-S | B9: SOUTHERN PERU COPPER CORPORATION | C9: 4100791028 | D9: Licitación 3000541921 CD_SERVICIO VARIADOR ROCKWELL_R | E9: 46056 | F9: 46062 | G9: 5644.8 | H9: 4844 | I9: 0 | J9: 0 | K9: 800.8 | L9: Claudia | N9: SHAHUINDO S.A.C. | O9: =SUMIF(B:B,"SHAHUINDO S.A.C.",G:G) | P9: =COUNTIF(B:B,"SHAHUINDO S.A.C.")
A10: 262014A-SPCC-V | B10: SOUTHERN PERU COPPER CORPORATION | C10: 4100792483 | D10: LICENCIA WINCC SPCC | E10: 46063 | F10: 46077 | G10: 2272.58 | H10: 1976.16 | I10: 0 | J10: 0 | K10: 296.42 | L10: Eduardo | N10: SOUTHERN PERU COPPER CORPORATION | O10: =SUMIF(B:B,"SOUTHERN PERU COPPER CORPORATION",G:G) | P10: =COUNTIF(B:B,"SOUTHERN PERU COPPER CORPORATION")
A11: 262013A-MY-S | B11: MINERA YANACOCHA | C11: 3003201873 | D11: PR 1006282742 - Migración lógica controladores PLC5/40 y SLC500 (Allen Bradley) Planta procesos | E11: 46069 | F11: 46092 | G11: 14658 | H11: 0 | I11: 13230 | J11: 0 | K11: 1428 | L11: Luisa | N11: YURA S.A. | O11: =SUMIF(B:B,"YURA S.A.",G:G) | P11: =COUNTIF(B:B,"YURA S.A.")
A12: 262015A-MY-S | B12: MINERA YANACOCHA | C12: 3003205374 | D12: RFQ 1006293632 - MIGRACIÓN I/O PLC5 – YN BOOSTER KM45 | E12: 46069 | F12: 46129 | G12: 7260 | H12: 0 | I12: 6600 | J12: 0 | K12: 660 | L12: Eduardo | O12: =SUM(G3:G33) | P12: =COUNTA(A3:A33)
A13: 262037A-MMG-V | B13: MINERA LAS BAMBAS S.A. | C13: 4400672314 | D13: RFQ 6000121001 Accesorios Dixon | E13: 46071 | F13: 46074 | G13: 329.97 | H13: 213.81 | I13: 0 | J13: 0 | K13: 116.16 | L13: Claudia
A14: 262046A-SHA-V | B14: SHAHUINDO S.A.C. | C14: 50167 | D14: LUMINARIA MODELO SOLARIS | E14: 46076 | F14: 46136 | G14: 35616 | H14: 31800 | I14: 0 | J14: 0 | K14: 3816 | L14: Eduardo | N14: Concepto | O14: Monto
A15: 262049A-MMG-V | B15: MINERA LAS BAMBAS S.A. | C15: 4400675551 | D15: MMG_RFQ No. 6000121455 Módulos IO Allen Bradley | E15: 46092 | F15: 46127 | G15: 1811.15 | H15: 1509.29 | I15: 0 | J15: 0 | K15: 301.86 | L15: Claudia | N15: Costo | O15: =SUM(H3:H33)
A16: 262062A-PREP-S | B16: Precision Peru SA | C16: 5328 | D16: TECNICOS ELÉCTRICOS - MINERA ANTAMINA - PDP ABRIL 2026 | E16: 46104 | F16: 46139 | G16: 7397.4 | H16: 3727 | I16: 3409.5 | J16: 0 | K16: 260.9 | L16: Eduardo | N16: HH Propia | O16: =SUM(I3:I33)
A17: 262056B-SPCC-S | B17: SOUTHERN PERU COPPER CORPORATION | C17: 4100801979 | D17: Licitación 3000553413 | E17: 46104 | F17: 46240 | G17: 10407.35 | H17: 8213.06 | I17: 901.7 | J17: 0 | K17: 1292.59 | L17: Luisa | N17: Imprevisto | O17: =SUM(J3:J33)
A18: 262041D-YURA-S | B18: YURA S.A. | C18: 4436612248 | D18: CTZ TABLEROS DE CONTROL | E18: 46112 | F18: 46217 | G18: 68932.01 | H18: 55771.83 | I18: 2805.1 | J18: 0 | K18: 10355.08 | L18: Luisa | N18: Utilidad | O18: =SUM(K3:K33)
A19: 262043D-MACO-S | B19: MARCOBRE S.A.C. | C19: 7700015783 | D19: CONCURSO 40052964- Mantenimiento de tableros y gabinetes de campo de sistema de control (HDCS & PLC) | E19: 46119 | F19: 46140 | G19: 34672 | H19: 24640 | I19: 8460 | J19: 0 | K19: 1572 | L19: Eduardo | O19: =SUM(O15:O18)
A20: 262069A-ANGQ-V | B20: ANGLO AMERICAN QUELLAVECO S.A. | C20: 4504223915 | D20: RFQ 6100160735 - sp 14584177 | E20: 46121 | F20: 46134 | G20: 1662.09 | H20: 1231.18 | I20: 0 | J20: 0 | K20: 430.91 | L20: Eduardo
A21: 262089A-SHA-V | B21: SHAHUINDO S.A.C. | C21: 51014 | D21: LUMINARIA MODELO SOLARIS | E21: 46148 | F21: 46188 | G21: 8904 | H21: 7950 | I21: 0 | J21: 0 | K21: 954 | L21: Eduardo | N21: KPI MIN | O21: =O16+O18
A22: 262075A-MACO-S | B22: MARCOBRE S.A.C. | C22: 7700015783 | D22: Pasajes Terrestre | E22: 46148 | F22: 46207 | G22: 2856 | H22: 2856 | I22: 0 | J22: 0 | K22: 0 | L22: Eduardo | N22: =NOW()
A23: 262064C-POD-S | B23: Compañía Minera Poderosa SA | C23: 4200022691-4200022692-4200022693 | D23: Remediación observaciones Auditoria PlantPAx | E23: 46167 | F23: 46178 | G23: 18140 | H23: 9740 | I23: 8400 | J23: 0 | K23: 0 | L23: Eduardo
A24: 262101A-PREP-S | B24: Precision Peru SA | C24: 5540 | D24: Servicio - TOQUEPALA | E24: 46169 | F24: 46179 | G24: 2487.12 | H24: 1848 | I24: 532.6 | J24: 0 | K24: 106.52 | L24: Eduardo
A25: 262104A-PREP-S | B25: Precision Peru SA | C25: 5605 | D25: MANTENIMIENTO 2 VFD - CONCENTRADORA 1 (NV - 25425) | E25: 46170 | F25: 46198 | G25: 3730.68 | H25: 2772 | I25: 798.9 | J25: 0 | K25: 159.78 | L25: Eduardo
A26: 262103A-MY-S | B26: MINERA YANACOCHA | C26: 3003254426 | D26: Migración - YN Recirculación | E26: 46171 | F26: 46231 | G26: 9680 | H26: 0 | I26: 8800 | J26: 0 | K26: 880 | L26: Luisa
A27: 262083B-MMG-S | B27: MINERA LAS BAMBAS S.A. | C27: 4400688949 | D27: PR_11684191_GABINETE GATEWAY 4.0 | E27: 46177 | F27: 46233 | G27: 3353.59 | H27: 2125 | I27: 867.8 | J27: 0 | K27: 360.79 | L27: Luisa
A28: 262107A-SPCC-S | B28: SOUTHERN PERU COPPER CORPORATION | C28: 4100776222 | D28: Tendido de tuberías conduit para cable de red en celdas Wemco y bombas Cleaner | E28: 46177 | F28: 46194 | G28: 12544.24 | H28: 7970 | I28: 3130.24 | J28: 0 | K28: 1444 | L28: Eduardo
A29: 262109A-PREP-S | B29: Precision Peru SA | C29: 5606 | D29: TECNICO ELÉCTRICO - MINERA ANTAMINA - PDP JUNIO 2026 | E29: 46177 | F29: 46195 | G29: 2453.36 | H29: 1004 | I29: 1207.8 | J29: 0 | K29: 241.56 | L29: Eduardo
A30: 252185H-YURA-S | B30: YURA S.A. | C30: 4436674328 | D30: Suministro Backpanel TC-Chancadora Primaria | E30: 46182 | F30: 46294 | G30: 47668.98 | H30: 40597.95 | I30: 4645.03 | J30: 0 | K30: 2426 | L30: Luisa
A31: 262121A-SPCC-P | B31: SOUTHERN PERU COPPER CORPORATION | C31: 4200009183, 4200009187, 4200009226, 4200009228, 4200009347, 4200009352 y 4200009353 | D31: LICITACIÓN P2255-001/P2255-002 - SUMINISTRO DE SISTEMA DE CONTROL Y COMUNICACIONES | E31: 46217 | F31: 46315 | G31: 268441.76 | H31: 228268.6 | I31: 17335.38 | J31: 0 | K31: 22837.78 | L31: Luisa
A32: 262012B-SPCC-P | B32: SOUTHERN PERU COPPER CORPORATION | C32: 4200003861 | D32: Licitación 3000563783 - MIGRACION DE PANTALLAS CON DISEÑO DE MIMICOS UTILIZANDO LIBRERIA PLANTPAX | E32: 46217 | F32: 46227 | G32: 4360 | H32: 860 | I32: 3500 | J32: 0 | K32: 0 | L32: Eduardo
A33: 262122A-MMG-V | B33: MINERA LAS BAMBAS S.A. | C33: 4400694917 | D33: Módulos IO Allen Bradley | E33: 46219 | F33: 46254 | G33: 632.84 | H33: 506.27 | I33: 0 | J33: 0 | K33: 126.57 | L33: Claudia
A34: TOTAL | G34: =SUM(G3:G33) | H34: =SUM(H3:H33) | I34: =SUM(I3:I33) | J34: =SUM(J3:J33) | K34: =SUM(K3:K33)

Sheet OIL
A1: ORDENES DE COMPRA PETROQUÍMICA
A2: CÓDIGO | B2: CLIENTES | C2: Nº Orden | D2: PROYECTO | E2: FECHA O/C | F2: FECHA ENTREGA | G2: VALOR PRESUPUESTO $ | H2: COSTO | I2: HH Propia | J2: IMPREVISTOS | K2: UTILIDAD | L2: Personal | N2: Empresa | O2: Monto O/C | P2: Cantidad
A3: 234061A-PTTL-P | B3: PETROTAL PERU S.R.L. | C3: 315-2023-064-1 | D3: Servicios de Soporte Técnico Especializado del Sistema de Control, Automatización y Almacenamiento | E3: 46008 | F3: 46363 | G3: 32050 | H3: 7960 | I3: 20075 | J3: 0 | K3: 4015 | L3: Eduardo | N3: PETROTAL PERU S.R.L. | O3: =SUMIF(B:B,"PETROTAL PERU S.R.L.",G:G) | P3: =COUNTIF(B:B,"PETROTAL PERU S.R.L.")
A4: 264004A-VALP-S | B4: Valero Peru S.A.C | C4: 4506904067 | D4: Actualización de Arquitectura de Red de Control y Memoria Descriptiva 2026 | E4: 46062 | F4: 46066 | G4: 660.71429 | H4: 125 | I4: 446.42857 | J4: 0 | K4: 89.285714 | L4: Eduardo | N4: SERTECPET | O4: =SUMIF(B:B,"SERTECPET",G:G) | P4: =COUNTIF(B:B,"SERTECPET")
A5: 264005A-TDP-S | B5: TERMINALES DEL PERÚ | C5: 34921 | D5: Programación y Visualización de señales de alarmas | E5: 46066 | F5: 46086 | G5: 3380 | H5: 1100 | I5: 1900 | J5: 0 | K5: 380 | L5: Luisa | N5: TERMINALES DEL PERÚ | O5: =SUMIF(B:B,"TERMINALES DEL PERÚ",G:G) | P5: =COUNTIF(B:B,"TERMINALES DEL PERÚ")
A6: 264002C-PTTL-P | B6: PETROTAL PERU S.R.L. | C6: 315-OC CNT-2023-064 | D6: Adenda - 315-CNT-2023-064 - Servicio de control y automatización - Lote 95 - 1 año | E6: 46081 | F6: 46387 | G6: 165000 | H6: 35668.33 | I6: 107675 | J6: 0 | K6: 21656.67 | L6: Eduardo | N6: Valero Peru S.A.C | O6: =SUMIF(B:B,"Valero Peru S.A.C",G:G) | P6: =COUNTIF(B:B,"Valero Peru S.A.C")
A7: 264010B-TDP-S | B7: TERMINALES DEL PERÚ | C7: 35462 | D7: Creación de nuevas operaciones en PLC | E7: 46093 | F7: 46099 | G7: 2240 | H7: 800 | I7: 1200 | J7: 0 | K7: 240 | L7: Eduardo | O7: =SUM(G3:G12) | P7: =COUNTA(A3:A12)
A8: 264011A-VALP-S | B8: Valero Peru S.A.C | C8: 4506906067 | D8: Actualización de planos del TCOM 2 y TCOM 3. | E8: 46094 | F8: 46108 | G8: 701.75439 | H8: 365.49708 | I8: 283.62573 | J8: 0 | K8: 52.631579 | L8: Eduardo
A9: 264017A-VALP-S | B9: Valero Peru S.A.C | C9: 4506976498 | D9: INTEGRACIÓN TANQUE B2 - SCADA | E9: 46171 | F9: 46176 | G9: 389.0411 | H9: 93.150685 | I9: 246.57534 | J9: 0 | K9: 49.315068 | L9: Claudia | N9: Concepto | O9: Monto
A10: 264018A-TDP-S | B10: TERMINALES DEL PERÚ | C10: 35852 | D10: Cambio de configuración de bombas de Diesel. | E10: 46182 | F10: 46183 | G10: 572 | H10: 212 | I10: 300 | J10: 0 | K10: 60 | L10: Eduardo | N10: costo | O10: =SUM(H3:H12)
A11: 264016B-SERTECPET-S | B11: SERTECPET | C11: POC0017247 | D11: Servicio de programación del Sistema de BPCS y SSS L2 EXTENDIDO DEL CAMPO BRETAÑA NORTE - Primera etapa (1-5) | E11: 46199 | F11: 46229 | G11: 21276.8 | H11: 1896.8 | I11: 17100 | J11: 0 | K11: 2280 | L11: Eduardo | N11: HH Propia | O11: =SUM(I3:I12)
A12: 264021A-VALP-S | B12: Valero Peru S.A.C | C12: None | D12: Integración de PTARI al SCADA. | E12: 46217 | F12: 46233 | G12: 880 | H12: 160 | I12: 600 | J12: 0 | K12: 120 | L12: Eduardo | N12: Imprevisto | O12: =SUM(J3:J12)
A13: TOTAL | G13: =SUM(G3:G12) | H13: =SUM(H3:H12) | I13: =SUM(I3:I12) | J13: =SUM(J3:J12) | K13: =SUM(K3:K12) | N13: Utilidad | O13: =SUM(K3:K12)
O14: =SUM(O10:O13)
N16: KPI OIL | O16: =O11+O13
N17: =NOW()

Sheet IND
A1: ORDENES DE COMPRA INDUSTRIA
A2: CÓDIGO | B2: CLIENTES | C2: Nº Orden | D2: PROYECTO | E2: FECHA O/C | F2: FECHA ENTREGA | G2: VALOR PRESUPUESTO $ | H2: COSTO | I2: HH Propia | J2: IMPREVISTOS | K2: UTILIDAD | L2: Personal | N2: Empresa | O2: Monto O/C | P2: Cantidad
A3: 261002A-RINTI-S | B3: RINTI S.A. | C3: 278386940 | D3: Temperatura silos 4000 | E3: 46010 | F3: 46022 | G3: 3300 | H3: 420 | I3: 2400 | J3: 0 | K3: 480 | L3: Claudia | N3: Casa Grande S.A.A. | O3: =SUMIF(B:B,"Casa Grande S.A.A.",G:G) | P3: =COUNTIF(B:B,"Casa Grande S.A.A.")
A4: 261007A-RINTI-V | B4: RINTI S.A. | C4: OPC2026 - 285410551 | D4: Canfield Connector Reed switch | E4: 46030 | F4: 46058 | G4: 532.5 | H4: 471 | I4: 0 | J4: 0 | K4: 61.5 | L4: Claudia | N4: MONDELEZ PERU S.A. | O4: =SUMIF(B:B,"MONDELEZ PERU S.A.",G:G) | P4: =COUNTIF(B:B,"MONDELEZ PERU S.A.")
A5: 251104B-TRUPAL-S | B5: TRUPAL S.A. | C5: 4602052586 | D5: Servicio de emergencia - Drive PF trupal Trujillo | E5: 46043 | F5: 46044 | G5: 366 | H5: 333 | I5: 0 | J5: 0 | K5: 33 | L5: Eduardo | N5: Nestle | O5: =SUMIF(B:B,"Nestle",G:G) | P5: =COUNTIF(B:B,"Nestle")
A6: 261009A-NESTLE-S | B6: Nestle | C6: 4580571581 | D6: Modificación SCADA para visualización sensores de Gas | E6: 46045 | F6: 46050 | G6: 1664.64 | H6: 700 | I6: 803.88 | J6: 0 | K6: 160.76 | L6: Eduardo | N6: RINTI S.A. | O6: =SUMIF(B:B,"RINTI S.A.",G:G) | P6: =COUNTIF(B:B,"RINTI S.A.")
A7: 261011A-NESTLE-S | B7: Nestle | C7: 4580661549 | D7: Revisión del PLC de los sensores de amoniaco | E7: 46058 | F7: 46061 | G7: 125.37313 | H7: 35.820896 | I7: 74.626866 | J7: 0 | K7: 14.925373 | L7: Eduardo | N7: TRUPAL S.A. | O7: =SUMIF(B:B,"TRUPAL S.A.",G:G) | P7: =COUNTIF(B:B,"TRUPAL S.A.")
A8: 261018A-MDZ-S | B8: MONDELEZ PERU S.A. | C8: 7333061880 | D8: CONFIGURACION DE RED INDUSTRIAL L5 | E8: 46073 | F8: 46112 | G8: 4101.8529 | H8: 1726.4706 | I8: 2159.3824 | J8: 0 | K8: 216 | L8: Claudia | O8: =SUM(G3:G15) | P8: =COUNTA(A3:A15)
A9: 261021A-CSSAA-P | B9: Casa Grande S.A.A. | C9: 4602099881 | D9: Servicio de soporte por emergencia PF7000 | E9: 46054 | F9: 46085 | G9: 4616 | H9: 3826 | I9: 0 | J9: 0 | K9: 790 | L9: Eduardo
A10: 251121A-MDZ-V | B10: MONDELEZ PERU S.A. | C10: 7333081135 | D10: Suministro de licencias SQL | E10: 46058 | F10: 46064 | G10: 1163.9286 | H10: 825.68571 | I10: 0 | J10: 0 | K10: 338.24286 | L10: Eduardo | N10: Concepto | O10: Monto
A11: 261028B-MDZ-S | B11: MONDELEZ PERU S.A. | C11: 7333101068 | D11: Migración de Switches Strarix 5700 a Stratix 5200 - L5 | E11: 46119 | F11: 46149 | G11: 2857.1429 | H11: 1968.5714 | I11: 807.14286 | J11: 0 | K11: 81.428571 | L11: Claudia | N11: costo | O11: =SUM(H3:H15)
A12: 261019B-RINTI-S | B12: RINTI S.A. | C12: 285411940 | D12: INTEGRACIÓN Y CABLEADO DE VALVULA DE DISTRIBUIDOR DE MAÍZ (SILO 4000) | E12: 46108 | F12: 46170 | G12: 2180 | H12: 380 | I12: 1500 | J12: 0 | K12: 300 | L12: Claudia | N12: HH Propia | O12: =SUM(I3:I15)
A13: 261032A-NESTLE-S | B13: Nestle | C13: 4581800203 | D13: Parada de compresores Sala Vilter con sensor de amoniaco | E13: 46188 | F13: 46198 | G13: 251.42857 | H13: 45.714286 | I13: 171.42857 | J13: 0 | K13: 34.285714 | L13: Claudia | N13: Imprevisto | O13: =SUM(J3:J15)
A14: 261037B-RINTI-S | B14: RINTI S.A. | C14: None | D14: Actualización de Filosofía de Control de Multipartículas 2 | E14: 46213 | F14: 46230 | G14: 3455 | H14: 906.96 | I14: 2060 | J14: 0 | K14: 488.04 | L14: Eduardo | N14: Utilidad | O14: =SUM(K3:K15)
A15: 261025C-NESTLE-S | B15: Nestle | C15: 4582046265 | D15: PE_Automatización de cambio de agua de desmolde de bombones_RFP_052026. | E15: 46217 | F15: 46266 | G15: 3554.4444 | H15: 2058.8889 | I15: 1192.5 | J15: 0 | K15: 303.05556 | L15: Claudia | O15: =SUM(O11:O14)
A16: TOTAL | G16: =SUM(G3:G15) | H16: =SUM(H3:H15) | I16: =SUM(I3:I15) | J16: =SUM(J3:J15) | K16: =SUM(K3:K15)
N18: Por Facturar | O18: 0
N19: Facturado | O19: 0
O20: =SUM(O18:O19)
N22: KPI IND | O22: =O12+O14
N23: =NOW()

Sheet SFY
A1: ORDENES DE COMPRA SEGURIDAD DE MAQUINARIA
A2: CÓDIGO | B2: CLIENTES | C2: Nº Orden | D2: PROYECTO | E2: FECHA O/C | F2: FECHA ENTREGA | G2: VALOR PRESUPUESTO $ | H2: COSTO | I2: HH Propia | J2: IMPREVISTOS | K2: UTILIDAD | L2: Personal | N2: Empresa | O2: Monto | P2: Cantidad
A3: TOTAL | G3: 0 | H3: 0 | I3: 0 | J3: 0 | K3: 0 | O3: =SUM(G3:G2) | P3: =COUNTA(A3:A2)
N5: Concepto | O5: Monto
N6: costo | O6: =SUM(H3:H2)
N7: HH Propia | O7: =SUM(I3:I2)
N8: Imprevisto | O8: =SUM(J3:J2)
N9: Utilidad | O9: =SUM(K3:K2)
O10: =SUM(O6:O9)
N13: Por Facturar | O13: 0
N14: Facturado | O14: 0
O15: =SUM(O13:O14)
N17: KPI SFY | O17: =O7+O9
N18: =NOW()

Sheet 2012 - 2026
A2: Gerencia | B2: Monto OC | C2: Cantidad | I2: Año | J2: Montos OC | K2: HH+Utilidad | L2: Objetivo Mínimo | M2: Cantidad
A3: IND | B3: =IND!O8 | C3: =IND!P8 | I3: 2012 | J3: 856894.56 | K3: 0 | M3: 132
A4: MIN | B4: =MIN!O12 | C4: =MIN!P12 | I4: 2013 | J4: 1173006.5 | K4: 0 | M4: 172
A5: OIL | B5: =OIL!O7 | C5: =OIL!P7 | I5: 2014 | J5: 1469563.6 | K5: 766989.82 | L5: 599213.69 | M5: 198
A6: SFY | B6: =SFY!O3 | C6: =SFY!P3 | I6: 2015 | J6: 1267166.7 | K6: 530501.63 | L6: 791852.48 | M6: 231
A7: Total | B7: =SUM(B3:B6) | C7: =SUM(C3:C6) | I7: 2016 | J7: 1080847.1 | K7: 507030.85 | L7: 791852.48 | M7: 134
I8: 2017 | J8: 1415889.7 | K8: 473934.38 | L8: 786394.2 | M8: 158
I9: 2018 | J9: 1690561 | K9: 674026.11 | L9: 1015424.4 | M9: 181
I10: 2019 | J10: 2113662.1 | K10: 590483.95 | L10: 1016302.2 | M10: 176
I11: 2020 | J11: 1428707.6 | K11: 712348.38 | L11: 869409.41 | M11: 101
I12: 2021 | J12: 1174629.1 | K12: 361921.25 | L12: 864817.23 | M12: 119
I13: 2022 | J13: 1568894.2 | K13: 573851.61 | L13: 726996.85 | M13: 93
I14: 2023 | J14: 1601964.3 | K14: 855738.59 | L14: 872396.23 | M14: 98
I15: 2024 | J15: 1502315 | K15: 827619.79 | L15: 1046875.5 | M15: 110
I16: 2025 | J16: 1580195.6 | K16: 734535.75 | L16: 1046875.5 | M16: 87
I17: 2026 | J17: =B7 | K17: =Objetivos!D7 | L17: =Objetivos!C7 | M17: =C7
A25: INDUSTRIA
A26: Año | B26: ENE | C26: FEB | D26: MAR | E26: ABR | F26: MAY | G26: JUN | H26: JUL | I26: AGO | J26: SEP | K26: OCT | L26: NOV | M26: DIC | N26: Total
A27: 2011 | B27: 0 | C27: 0 | D27: 8081.84 | E27: 1225.4545 | F27: 0 | G27: 1996 | H27: 840.55 | I27: 34797.82 | J27: 0 | K27: 111991.51 | L27: 6400 | M27: 9116.67 | N27: =SUM(B27:M27)
A28: 2012 | B28: 288.75 | C28: 16966.01 | D28: 11996.84 | E28: 10473.8 | F28: 23696.62 | G28: 17358.2 | H28: 11531.73 | I28: 11142.81 | J28: 3372.72 | K28: 370.5 | L28: 38269.66 | M28: 20800.84 | N28: =SUM(B28:M28)
A29: 2013 | B29: 14551.34 | C29: 19427.05 | D29: 2262 | E29: 39092.38 | F29: 31540.28 | G29: 19834.15 | H29: 3903.08 | I29: 49596.05 | J29: 11850.33 | K29: 28657.57 | L29: 34503.31 | M29: 0 | N29: =SUM(B29:M29)
A30: 2014 | B30: 35533.57 | C30: 3500 | D30: 13796 | E30: 6360 | F30: 34670 | G30: 20700 | H30: 27649.9 | I30: 12924.2 | J30: 71445.26 | K30: 125296.03 | L30: 19935.01 | M30: 19950 | N30: =SUM(B30:M30)
A31: 2015 | B31: 0 | C31: 0 | D31: 48338.97 | E31: 1619.9 | F31: 400 | G31: 54648.3 | H31: 11186.8 | I31: 32656.2 | J31: 40006.21 | K31: 7070.13 | L31: 12900 | M31: 59189 | N31: =SUM(B31:M31)
A32: 2016 | B32: 64626.94 | C32: 91133.37 | D32: 28155.6 | E32: 1222.5 | F32: 600 | G32: 3688.4 | H32: 25934.95 | I32: 15845.01 | J32: 4185.51 | K32: 12128.1 | L32: 3807.88 | M32: 4900 | N32: =SUM(B32:M32)
A33: 2017 | B33: 19607.87 | C33: 133750.17 | D33: 23056.54 | E33: 1982 | F33: 41474 | G33: 5405.5 | H33: 144797.51 | I33: 147549.01 | J33: 8547.44 | K33: 2414.93 | L33: 65256.13 | M33: 49307.3 | N33: =SUM(B33:M33)
A34: 2018 | B34: 47082.85 | C34: 26269.61 | D34: 65385.66 | E34: 22090.56 | F34: 142594.25 | G34: 4320 | H34: 2814.7 | I34: 17059.71 | J34: 18378 | K34: 10400 | L34: 88735.86 | M34: 6045.56 | N34: =SUM(B34:M34)
A35: 2019 | B35: 11400.28 | C35: 9990 | D35: 0 | E35: 2682.46 | F35: 95953.7 | G35: 22179.66 | H35: 0 | I35: 9915.6 | J35: 800 | K35: 850 | L35: 11258.1 | M35: 0 | N35: =SUM(B35:M35)
A36: 2020 | B36: 11188.55 | C36: 33333.2 | D36: 0 | E36: 0 | F36: 0 | G36: 0 | H36: 16924.46 | I36: 110 | J36: 1354.46 | K36: 1452.34 | L36: 3544.38 | M36: 7272 | N36: =SUM(B36:M36)
A37: 2021 | B37: 8601.17 | C37: 0 | D37: 1104.57 | E37: 4337.71 | F37: 0 | G37: 0 | H37: 155 | I37: 202961.72 | J37: 127.78 | K37: 7402.35 | L37: 2438 | M37: 1206 | N37: =SUM(B37:M37)
A38: 2022 | B38: 0 | C38: 1801.85 | D38: 6522.74 | E38: 11039.54 | F38: 471.6 | G38: 14709 | H38: 0 | I38: 9710 | J38: 100 | K38: 17001.24 | L38: 1130 | M38: 0 | N38: =SUM(B38:M38)
... A42: 2026 | B42: 2563.14 | C42: 23056.05 | D42: 2180 | E42: 10000 | F42: 0 | G42: 880 | H42: 16251 | I42: 0 | J42: 0 | K42: 0 | L42: 0 | M42: 3300 | N42: =SUM(B42:M42)
A55: MINERIA
A56: Año | B56: ENE | C56: FEB | D56: MAR | E56: ABR | F56: MAY | G56: JUN | H56: JUL | I56: AGO | J56: SEP | K56: OCT | L56: NOV | M56: DIC | N56: Total
A57: 2011 | B57: 0 | C57: 0 | D57: 143668.9 | E57: 46280.65 | F57: 11504.24 | G57: 93709.46 | H57: 0 | I57: 41411.92 | J57: 22074.98 | K57: 51330.95 | L57: 10405 | M57: 78179.6 | N57: =SUM(B57:M57)
A58: 2012 | B58: 6016.7 | C58: 0 | D58: 272173.48 | E58: 9853.12 | F58: 13313.7 | G58: 8315.85 | H58: 9464.65 | I58: 2110.4 | J58: 2368 | K58: 0 | L58: 9172.15 | M58: 12995.65 | N58: =SUM(B58:M58)
A59: 2013 | B59: 9000 | C59: 6885 | D59: 222917.66 | E59: 59817.55 | F59: 394.4 | G59: 24251.24 | H59: 3454.21 | I59: 39736.85 | J59: 245081.41 | K59: 6332.89 | L59: 15281.25 | M59: 19860 | N59: =SUM(B59:M59)
A60: 2014 | B60: 38211.7 | C60: 9714.39 | D60: 74793.07 | E60: 270158.08 | F60: 92782.46 | G60: 9014.08 | H60: 26650.57 | I60: 12078.26 | J60: 123460.35 | K60: 138294.33 | L60: 24996.16 | M60: 24381.47 | N60: =SUM(B60:M60)
A61: 2015 | B61: 430.2 | C61: 13222.02 | D61: 118619.54 | E61: 53498.21 | F61: 251484.85 | G61: 108690.8 | H61: 82851.87 | I61: 221857.22 | J61: 13438.53 | K61: 165667.24 | L61: 58231.71 | M61: 7455.68 | N61: =SUM(B61:M61)
A62: 2016 | B62: 72022.04 | C62: 1333.87 | D62: 173190.1 | E62: 0 | F62: 5926.71 | G62: 0 | H62: 34536.83 | I62: 129249.84 | J62: 230.94 | K62: 146213.87 | L62: 71232.6 | M62: 20314.5 | N62: =SUM(B62:M62)
A63: 2017 | B63: 230561.94 | C63: 4217.06 | D63: 24524.97 | E63: 31573.59 | F63: 63558.07 | G63: 14802.02 | H63: 67282.87 | I63: 64937.37 | J63: 17097.45 | K63: 41572.12 | L63: 129161.75 | M63: 111130.58 | N63: =SUM(B63:M63)
...

Sheet Objetivos
A1: COMPARTIVA DE OBJETIVOS Y METAS
A2: ÁREA | B2: OBJETIVO ANUAL MÁXIMO | C2: OBJETIVO ANUAL MÍNIMO | D2: LOGRADO | E2: OBJETIVO MAX MENSUAL | F2: OBJETIVO MIN MENSUAL | G2: DIFERENCIA C/ MÍNIMO | H2: DIFERENCIA C/ MÁXIMO | I2: FALTANTE AL MÍNIMO | J2: FALTANTE AL MÁXIMO | L2: Año | M2: Logrado
A3: MIN | B3: 625000 | C3: 615000 | D3: =MIN!O21 | E3: =B3/12*8 | F3: =C3/12*8 | G3: =D3-F3 | H3: =D3-E3 | I3: =D3-C3 | J3: =D3-B3 | L3: 2014 | M3: 599213.69
A4: IND | B4: 260000 | C4: 250000 | D4: =IND!O22 | E4: =B4/12*8 | F4: =C4/12*8 | G4: =D4-F4 | H4: =D4-E4 | I4: =D4-C4 | J4: =D4-B4 | L4: 2015 | M4: 791852.48
A5: OIL | B5: 230000 | C5: 220000 | D5: =OIL!O16 | E5: =B5/12*8 | F5: =C5/12*8 | G5: =D5-F5 | H5: =D5-E5 | I5: =D5-C5 | J5: =D5-B5 | L5: 2016 | M5: 546600.85
A6: SFY | B6: 90000 | C6: 80000 | D6: =SFY!O17 | E6: =B6/12*8 | F6: =C6/12*8 | G6: =D6-F6 | H6: =D6-E6 | I6: =D6-C6 | J6: =D6-B6 | L6: 2017 | M6: 586456.22
A7: TOTALES | B7: =SUM(B3:B6) | C7: =SUM(C3:C6) | D7: =SUM(D3:D6) | E7: =SUM(E3:E6) | F7: =SUM(F3:F6) | G7: =D7-F7 | H7: =D7-E7 | I7: =D7-C7 | J7: =D7-B7 | L7: 2018 | M7: 815521.11
L8: 2019 | M8: 706732.22
C9: Faltante al Mínimo | D9: =C7-D7 | L9: 2020 | M9: 820464.89
C10: Faltante al Máximo | D10: =B7-D7 | L10: 2021 | M10: 475934.45
L11: 2022 | M11: 764082.81
L12: 2023 | M12: 832552.59
B13: MÁXIMO | D13: MÍNIMO | L13: 2024 | M13: 865726.08
B14: Avance | C14: Faltante | D14: Avance | E14: Faltante | L14: 2025 | M14: 787520.06
A15: MIN | B15: =(D3*100/E3)% | C15: =IF(B15>=1,0,1-B15) | D15: =(D3*100/F3)% | E15: =IF(D15>=1,0,1-D15) | L15: 2026 | M15: =D7
A16: IND | B16: =(D4*100/E4)% | C16: =IF(B16>=1,0,1-B16) | D16: =(D4*100/F4)% | E16: =IF(D16>=1,0,1-D16)
A17: OIL | B17: =(D5*100/E5)% | C17: =IF(B17>=1,0,1-B17) | D17: =(D5*100/F5)% | E17: =IF(D17>=1,0,1-D17)
A18: SFY | B18: =(D6*100/E6)% | C18: =IF(B18>=1,0,1-B18) | D18: =(D6*100/F6)% | E18: =IF(D18>=1,0,1-D18)
A19: V&C | B19: =(D7*100/E7)% | C19: =IF(B19>=1,0,1-B19) | D19: =(D7*100/F7)% | E19: =IF(D19>=1,0,1-D19)
B39: Métrica | C39: Avance | D39: Faltante
B40: Avance MIN | C40: =D7/C7 | D40: =MAX(0, 1-C40)
B41: Avance MAX | C41: =D7/B7 | D41: =MAX(0, 1-C41)

Sheet Objetivos Com.
A1: MIN | B1: NOMBRE | C1: MAX | D1: MIN | E1: PRO. TRA. | F1: Obj. Max | G1: Obj. Min | H1: Conseguido | I1: % Max | J1: % Min
B2: Ana Claudia Carbonel Gomero | C2: =Objetivos!B3 | D2: =Objetivos!C3 | E2: 0.33333333 | F2: =C$2*E2 | G2: =D$2*E2 | H2: =SUMIF(MIN!L:L,"Claudia",MIN!I:I)+SUMIF(MIN!L:L,"Claudia",MIN!K:K) | I2: =IF(F2>0,H2/F2,0) | J2: =IF(G2>0,H2/G2,0)
B3: Luisa Oncebay Delgado | E3: 0.33333333 | F3: =C$2*E3 | G3: =D$2*E3 | H3: =SUMIF(MIN!L:L,"Luisa",MIN!I:I)+SUMIF(MIN!L:L,"Luisa",MIN!K:K) | I3: =IF(F3>0,H3/F3,0) | J3: =IF(G3>0,H3/G3,0)
B4: Pedro Eduardo Bonilla Cornejo | E4: 0.33333333 | F4: =C$2*E4 | G4: =D$2*E4 | H4: =SUMIF(MIN!L:L,"Eduardo",MIN!I:I)+SUMIF(MIN!L:L,"Eduardo",MIN!K:K) | I4: =IF(F4>0,H4/F4,0) | J4: =IF(G4>0,H4/G4,0)
B5: TOTAL | E5: =SUM(E2:E4) | F5: =SUM(F2:F4) | G5: =SUM(G2:G4) | H5: =SUM(H2:H4) | I5: =IF(F5>0,H5/F5,0) | J5: =IF(G5>0,H5/G5,0)
A8: IND | B8: NOMBRE | C8: MAX | D8: MIN | E8: PRO. TRA. | F8: Obj. Max | G8: Obj. Min | H8: Conseguido | I8: % Max | J8: % Min
B9: Ana Claudia Carbonel Gomero | C9: =Objetivos!B4 | D9: =Objetivos!C4 | E9: 0.33333333 | F9: =C$9*E9 | G9: =D$9*E9 | H9: =SUMIF(IND!L:L,"Claudia",IND!I:I)+SUMIF(IND!L:L,"Claudia",IND!K:K) | I9: =IF(F9>0,H9/F9,0) | J9: =IF(G9>0,H9/G9,0)
B10: Luisa Oncebay Delgado | E10: 0.33333333 | F10: =C$9*E10 | G10: =D$9*E10 | H10: =SUMIF(IND!L:L,"Luisa",IND!I:I)+SUMIF(IND!L:L,"Luisa",IND!K:K) | I10: =IF(F10>0,H10/F10,0) | J10: =IF(G10>0,H10/G10,0)
B11: Pedro Eduardo Bonilla Cornejo | E11: 0.33333333 | F11: =C$9*E11 | G11: =D$9*E11 | H11: =SUMIF(IND!L:L,"Eduardo",IND!I:I)+SUMIF(IND!L:L,"Eduardo",IND!K:K) | I11: =IF(F11>0,H11/F11,0) | J11: =IF(G11>0,H11/G11,0)
B12: TOTAL | E12: =SUM(E9:E11) | F12: =SUM(F9:F11) | G12: =SUM(G9:G11) | H12: =SUM(H9:H11) | I12: =IF(F12>0,H12/F12,0) | J12: =IF(G12>0,H12/G12,0)
A15: OIL | B15: NOMBRE | C15: MAX | D15: MIN | E15: PRO. TRA. | F15: Obj. Max | G15: Obj. Min | H15: Conseguido | I15: % Max | J15: % Min
B16: Ana Claudia Carbonel Gomero | C16: =Objetivos!B5 | D16: =Objetivos!C5 | E16: 0.33333333 | F16: =C$16*E16 | G16: =D$16*E16 | H16: =SUMIF(OIL!L:L,"Claudia",OIL!I:I)+SUMIF(OIL!L:L,"Claudia",OIL!K:K) | I16: =IF(F16>0,H16/F16,0) | J16: =IF(G16>0,H16/G16,0)
B17: Luisa Oncebay Delgado | E17: 0.33333333 | F17: =C$16*E17 | G17: =D$16*E17 | H17: =SUMIF(OIL!L:L,"Luisa",OIL!I:I)+SUMIF(OIL!L:L,"Luisa",OIL!K:K) | I17: =IF(F17>0,H17/F17,0) | J17: =IF(G17>0,H17/G17,0)
B18: Pedro Eduardo Bonilla Cornejo | E18: 0.33333333 | F18: =C$16*E18 | G18: =D$16*E18 | H18: =SUMIF(OIL!L:L,"Eduardo",OIL!I:I)+SUMIF(OIL!L:L,"Eduardo",OIL!K:K) | I18: =IF(F18>0,H18/F18,0) | J18: =IF(G18>0,H18/G18,0)
B19: TOTAL | E19: =SUM(E16:E18) | F19: =SUM(F16:F18) | G19: =SUM(G16:G18) | H19: =SUM(H16:H18) | I19: =IF(F19>0,H19/F19,0) | J19: =IF(G19>0,H19/G19,0)
A22: SFY | B22: NOMBRE | C22: MAX | D22: MIN | E22: PRO. TRA. | F22: Obj. Max | G22: Obj. Min | H22: Conseguido | I22: % Max | J22: % Min
B23: Ana Claudia Carbonel Gomero | C23: =Objetivos!B6 | D23: =Objetivos!C6 | E23: 0.33333333 | F23: =C$23*E23 | G23: =D$23*E23 | H23: =SUMIF(SFY!L:L,"Claudia",SFY!I:I)+SUMIF(SFY!L:L,"Claudia",SFY!K:K) | I23: =IF(F23>0,H23/F23,0) | J23: =IF(G23>0,H23/G23,0)
B24: Luisa Oncebay Delgado | E24: 0.33333333 | F24: =C$23*E24 | G24: =D$23*E24 | H24: =SUMIF(SFY!L:L,"Luisa",SFY!I:I)+SUMIF(SFY!L:L,"Luisa",SFY!K:K) | I24: =IF(F24>0,H24/F24,0) | J24: =IF(G24>0,H24/G24,0)
B25: Pedro Eduardo Bonilla Cornejo | E25: 0.33333333 | F25: =C$23*E25 | G25: =D$23*E25 | H25: =SUMIF(SFY!L:L,"Eduardo",SFY!I:I)+SUMIF(SFY!L:L,"Eduardo",SFY!K:K) | I25: =IF(F25>0,H25/F25,0) | J25: =IF(G25>0,H25/G25,0)
B26: TOTAL | E26: =SUM(E23:E25) | F26: =SUM(F23:F25) | G26: =SUM(G23:G25) | H26: =SUM(H23:H25) | I26: =IF(F26>0,H26/F26,0) | J26: =IF(G26>0,H26/G26,0)
B29: Area | C29: Cuota Comercial | D29: Conseguido | E29: %
B30: Minería | C30: =C2 | D30: =SUM(H2:H4) | E30: =IF(C30>0,D30/C30,0)
B31: Industria | C31: =C9 | D31: =SUM(H9:H11) | E31: =IF(C31>0,D31/C31,0)
B32: Petroquímica | C32: =C16 | D32: =SUM(H16:H18) | E32: =IF(C32>0,D32/C32,0)
B33: Safety | C33: =C23 | D33: =SUM(H23:H25) | E33: =IF(C33>0,D33/C33,0)
B34: Total | C34: =SUM(C30:C33) | D34: =SUM(D30:D33) | E34: =IF(C34>0,D34/C34,0)
B37: Nombre Vendedor | C37: Conseguido
B38: Ana Claudia Carbonel Gomero | C38: =H2+H9+H16+H23
B39: Luisa Oncebay Delgado | C39: =H3+H10+H17+H24
B40: Pedro Eduardo Bonilla Cornejo | C40: =H4+H11+H18+H25
B41: Total | C41: =SUM(C38:C40)
