Workbook

Sheet MIN
A1: ORDENES DE COMPRA MINERÍA
A2: CÓDIGO | B2: CLIENTES | C2: N° Orden | D2: PROYECTO | E2: FECHA O/C | F2: FECHA ENTREGA | G2: VALOR PRESUPUESTO $ | H2: COSTO | I2: HH Propia | J2: IMPREVISTOS | K2: UTILIDAD | L2: Personal | N2: =SUM(G:G) -> 1144091.1 | P2: =COUNTA(A3:A444) -> 31
A3: 222023A-ANGQ-P_05 | B3: Quellaveco | C3: 2MAY3279-CON-0001 | D3: Mantenimiento de Redes de Comunicación Industrial, Componentes del Sistema de Control | E3: 46023 | F3: 46387 | G3: 521378.4 | H3: =9554.04+210078.24 -> 219632.28 | I3: 237615 | J3: 8497.82 | K3: 55633.3 | L3: Eduardo | M3: Empresa | N3: Monto O/C | O3: Empresa | P3: Total
A4: 262003A-PREP-S | B4: Precisión | C4: 5000 | D4: Servicio de técnicos perfil eléctrico | E4: 46020 | F4: 45682 | G4: 1992.68 | H4: 644 | I4: 1123.9 | J4: 0 | K4: 224.78 | L4: Eduardo | M4: Quellaveco | N4: =SUMIF(B:B,"quellaveco",G:G) -> 523040.49 | O4: Las Bambas | P4: =COUNTIF(B:B,"Las bambas") -> 5
A5: 262010A-PREP-V | B5: Precisión | D5: Equipos de Proteccion Personal | E5: 46034 | F5: 46037 | G5: 552.68 | H5: 552.68 | I5: 0 | J5: 0 | K5: 0 | L5: Eduardo | M5: SPCC | N5: =SUMIF(B:B,"Southern",G:G) -> 316454.67 | O5: SPCC | P5: =COUNTIF(B:B,"Southern") -> 7
A6: 262016B-SHA-V | B6: Shahuindo | C6: 49857 | D6: LUMINARIA MODELO SOLARIS SOLICITUD 177391 | E6: 46048 | F6: 46106 | G6: 29680 | H6: 26500 | I6: 0 | J6: 0 | K6: 3180 | L6: Eduardo | M6: Shahuindo | N6: =SUMIF(B:B,"shahuindo",G:G) -> 74200 | O6: Quellaveco | P6: =COUNTIF(B:B,"Quellaveco") -> 2
A7: 262028A-MMG-V | B7: Las Bambas | C7: 4400669247 | D7: Solicitud de cotización S1045572-shneider | E7: 46051 | F7: 46058 | G7: 1787.49 | H7: 1191.66 | I7: 0 | J7: 0 | K7: 595.83 | L7: Luisa | M7: Las Bambas | N7: =SUMIF(B:B,"Las bambas",G:G) -> 7915.04 | O7: Yura | P7: =COUNTIF(B:B,"Yura") -> 2
A8: 262022A-SPCC-V | B8: Southern | C8: 4100790414 | D8: Licitación 3000545027 ST VARIOS ELÉCTRICOS | E8: 46055 | F8: 46126 | G8: 12783.94 | H8: 11161.28 | I8: 0 | J8: 0 | K8: 1622.66 | L8: Eduardo | M8: Shougang | N8: =SUMIF(B:B,"Shougang",G:G) -> 0 | O8: Precisión | P8: =COUNTIF(B:B,"precisión") -> 6
A9: 262009B-SPCC-S | B9: Southern | C9: 4100791028 | D9: Licitación 3000541921 CD_SERVICIO VARIADOR ROCKWELL_R | E9: 46056 | F9: 46062 | G9: 5644.8 | H9: =840+4004 -> 4844 | I9: 0 | J9: 0 | K9: 800.8 | L9: Claudia | M9: Andalucita | N9: =SUMIF(B:B,"andalucita",G:G) -> 0 | O9: Shougang | P9: =COUNTIF(B:B,"Shougang") -> 0
A10: 262014A-SPCC-V | B10: Southern | C10: 4100792483 | D10: LICENCIA WINCC SPCC | E10: 46063 | F10: 46083 | G10: 2272.58 | H10: 1976.16 | I10: 0 | J10: 0 | K10: 296.42 | L10: Claudia | M10: Yura | N10: =SUMIF(B:B,"yura",G:G) -> 116600.99 | O10: Andalucita | P10: =COUNTIF(B:B,"andalucita") -> 0
A11: 262013A-MY-S | B11: Yanacocha | C11: 3003201873 | D11: Migración lógica controladores PLC540 y SLC500 (Allen Bradley) Planta procesos | E11: 46069 | F11: 46092 | G11: 14658 | H11: 0 | I11: 13230 | J11: 0 | K11: 1428 | L11: Eduardo | M11: La Arena | N11: =SUMIF(B:B,"la arena",G:G) -> 0 | O11: La Arena | P11: =COUNTIF(B:B,"la arena") -> 0
A12: 262015A-MY-S | B12: Yanacocha | C12: 3003205374 | D12: MIGRACIÓN IO PLC5 – YN BOOSTER KM45 | E12: 46069 | F12: 46130 | G12: 7260 | H12: 0 | I12: 6600 | J12: 0 | K12: 660 | L12: Eduardo | M12: Precisión | N12: =SUMIF(B:B,"precisión",G:G) -> 18613.92 | O12: Shahuindo | P12: =COUNTIF(B:B,"shahuindo") -> 3
A13: 262037A-MMG-V | B13: Las Bambas | C13: 4400672314 | D13: RFQ 6000121001 Accesorios Dixon | E13: 46071 | F13: 46074 | G13: 329.97 | H13: 213.81 | I13: 0 | J13: 0 | K13: 116.16 | L13: Claudia | M13: Antapacay | N13: =SUMIF(B:B,"Antapacay",G:G) -> 0 | O13: Marcobre | P13: =COUNTIF(B:B,"marcobre") -> 2
A14: 262046A-SHA-V | B14: Shahuindo | C14: 50167 | D14: Luminarias Solares OC | E14: 46076 | F14: 46136 | G14: 35616 | H14: 31800 | I14: 0 | J14: 0 | K14: 3816 | L14: Eduardo | M14: Marcobre | N14: =SUMIF(B:B,"marcobre",G:G) -> 37528 | O14: SIHI | P14: =COUNTIF(B:B,"sihi") -> 0
A15: 262049A-MMG-V | B15: Las Bambas | C15: 4400675551 | D15: Modulos IO AB | E15: 46094 | F15: 46127 | G15: 1811.15 | H15: 1509.29 | I15: 0 | J15: 0 | K15: 301.86 | L15: Claudia | M15: Volcan | N15: =SUMIF(B:B,"volcan",G:G) -> 0 | O15: Gloria | P15: =COUNTIF(B:B,"gloria") -> 0
A16: 262062A-PREP-S | B16: Precisión | D16: TECNICOS ELÉCTRICOS - MINERA ANTAMINA - PDP ABRIL 2026 | E16: 46104 | F16: 46130 | G16: 7397.4 | H16: 3306 | I16: 3409.5 | J16: 0 | K16: 681.9 | L16: Eduardo | M16: Alpayana | N16: =SUMIF(B:B,"alpayana",G:G) -> 0 | O16: Chinalco | P16: =COUNTIF(B:B,"chinalco") -> 0
A17: 262056B-SPCC-S | B17: Southern | C17: 4100801979 | D17: Licitación 3000553413 Tablero | E17: 46104 | F17: 46240 | G17: 10407.35 | H17: =7341.06+800 -> 8141.06 | I17: 901.7 | J17: 72 | K17: 1292.59 | L17: Luisa | M17: Suez | N17: =SUMIF(B:B,"suez",G:G) -> 0 | O17: Chaglla | P17: =COUNTIF(B:B,"Chaglla") -> 0
A18: 262041D-YURA-S | B18: Yura | D18: CTZ TABLEROS DE CONTROL | E18: 46112 | F18: 46217 | G18: 68932.01 | H18: =53127.83+1800 -> 54927.83 | I18: 2805.1 | J18: 844 | K18: 10355.08 | L18: Luisa | M18: Peru Process | N18: =SUMIF(B:B,"Peru Process",G:G) -> 0 | O18: Antapacay | P18: =COUNTIF(B:B,"Antapacay") -> 0
A19: 262043D-MACO-S | B19: Marcobre | C19: 7700015783 | D19: Mantenimiento de tableros y gabinetes de campo de sistema de control (HDCS & PLC) | E19: 46119 | F19: 46140 | G19: 34672 | H19: 24640 | I19: 8460 | J19: 0 | K19: 1572 | L19: Eduardo | M19: Chaglla | N19: =SUMIF(B:B,"chaglla",G:G) -> 0 | O19: Peru Process | P19: =COUNTIF(B:B,"peru process") -> 0
A20: 262069A-ANGQ-V | B20: Quellaveco | C20: 4504223915 | D20: RFQ 6100160735 - sp 14584177 | E20: 46121 | F20: 46134 | G20: 1662.09 | H20: 1231.18 | I20: 0 | J20: 0 | K20: 430.91 | L20: Eduardo | M20: Chinalco | N20: =SUMIF(B:B,"chinalco",G:G) -> 0 | O20: Suez | P20: =COUNTIF(B:B,"suez") -> 0
A21: 262089A-SHA-V | B21: Shahuindo | C21: 51014 | D21: Luminarias Solaris | E21: 46148 | F21: 46188 | G21: 8904 | H21: 7950 | I21: 0 | J21: 0 | K21: 954 | L21: Eduardo | M21: Enaex | N21: =SUMIF(B:B,"enaex",G:G) -> 0 | O21: Tenova | P21: =COUNTIF(B:B,"tenova") -> 0
A22: 262075A-MACO-S | B22: Marcobre | D22: Transporte de MTTo | E22: 46148 | F22: 46218 | G22: 2856 | H22: 2856 | I22: 0 | J22: 0 | K22: 0 | L22: Eduardo | M22: Flottweg | N22: =SUMIF(B:B,"Flotweg",G:G) -> 0 | O22: Enaex | P22: =COUNTIF(B:B,"Enaex") -> 0
A23: 262064C-POD-S | B23: Poderosa | D23: Remediación observaciones Auditoria PlantPAx | E23: 46167 | F23: 46275 | G23: 18140 | H23: 9740 | I23: 8400 | J23: 0 | K23: 0 | L23: Eduardo | M23: Nexa | N23: =SUMIF(B:B,"nexa",G:G) -> 0 | O23: Nexa | P23: =COUNTIF(B:B,"nexa") -> 0
A24: 262101A-PREP-S | B24: Precisión | D24: Servicio - TOQUEPALA | E24: 46169 | F24: 46185 | G24: 2487.12 | H24: 1848 | I24: 532.6 | J24: 0 | K24: 106.52 | L24: Eduardo | M24: Tenova | N24: =SUMIF(B:B,"tenova",G:G) -> 0 | O24: Flottweg | P24: =COUNTIF(B:B,"flotweg") -> 0
A25: 262104A-PREP-S | B25: Precisión | D25: MANTENIMIENTO 2 VFD - CONCENTRADORA 1 (NV - 25425) | E25: 46170 | F25: 46198 | G25: 3730.68 | H25: 2772 | I25: 798.9 | J25: 0 | K25: 159.78 | L25: Eduardo
A26: 262103A-MY-S | B26: Yanacocha | C26: 3003254426 | D26: Migración - YN Recirculación | E26: 46171 | F26: 46230 | G26: 9680 | H26: 0 | I26: 8800 | J26: 0 | K26: 880 | L26: Luisa
A27: 262083B-MMG-S | B27: Las Bambas | C27: 4400688949 | D27: PR_11684191_GABINETE GATEWAY 4.0 | E27: 46177 | F27: 46233 | G27: 3353.59 | H27: =700+72+1353 -> 2125 | I27: 867.8 | J27: 0 | K27: 360.79 | L27: Luisa
A28: 262107A-SPCC-S | B28: Southern | D28: Tendido de tuberías conduit para cable de red en celdas Wemco y bombas Cleaner | E28: 46177 | F28: 46203 | G28: 12544.24 | H28: =1850+6120 -> 7970 | I28: =3130.24+480 -> 3610.24 | J28: 0 | K28: 964 | L28: Eduardo
A29: 262109A-PREP-S | B29: Precisión | D29: TECNICO ELÉCTRICO - MINERA ANTAMINA - PDP JUNIO 2026 | E29: 46177 | F29: 46203 | G29: 2453.36 | H29: 1004 | I29: 1207.8 | J29: 0 | K29: 241.56 | L29: Eduardo | M29: Monto Total | N29: =SUM(N4:N28) -> 1094353.1 | P29: =SUM(P4:P28) -> 27
A30: 252185H-YURA-S | B30: Yura | D30: Suministro Backpanel TC-Chancadora Primaria | E30: 46182 | F30: 46295 | G30: 47668.98 | H30: =6440+472+33685.95 -> 40597.95 | I30: 4645.03 | J30: 0 | K30: 2426 | L30: Luisa | N30: Concepto | O30: Monto
A31: 262121A-SPCC-P | B31: Southern | C31: 4200009183, 4200009187, 4200009226, 4200009228, 4200009347, 4200009352 y 4200009353 | D31: LICITACIÓN P2255-001/P2255-002 - SUMINISTRO DE SISTEMA DE CONTROL Y COMUNICACIONES | E31: 46217 | F31: 46321 | G31: 268441.76 | H31: =184614.28+43438.32+216 -> 228268.6 | I31: 17335.38 | J31: 0 | K31: 22837.78 | L31: Luisa | N31: Costo | O31: =SUM(H:H) -> 698769.05
A32: 262012B-SPCC-P | B32: Southern | C32: 4200003861 | D32: Licitación 3000563783 - MIGRACION DE PANTALLAS CON DISEÑO DE MIMICOS UTILIZANDO LIBRERIA PLANTPAX | E32: 46217 | F32: 46234 | G32: 4360 | H32: 860 | I32: 3500 | J32: 0 | K32: 0 | L32: Eduardo | N32: HH Propía | O32: =SUM(I:I) -> 323842.95
A33: 262122A-MMG-V | B33: Las Bambas | C33: 4400694917 | D33: Módulos IO Allen Bradley | E33: 46219 | F33: 46258 | G33: 632.84 | H33: 506.27 | I33: 0 | J33: 0 | K33: 126.57 | L33: Eduardo | N33: Imprevisto | O33: =SUM(J:J) -> 9413.82
N34: Utilidad | O34: =SUM(K:K) -> 112065.29
O35: =SUM(O31:O34) -> 1144091.1
N37: HH otras Areas | O37: =P55 -> 0
N39: KPI MIN | O39: =O32+O34 -> 435908.24
N40: =NOW() -> 46237.384
N45: Detalle HH otras Areas
N46: Proyecto | O46: Detalle | P46: HH
...

Sheet OIL
B1: ORDENES DE COMPRA PETROQUÍMICA
A2: CÓDIGO | B2: CLIENTES | C2: N° Orden | D2: PROYECTO | E2: FECHA O/C | F2: FECHA ENTREGA | G2: VALOR PRESUPUESTO $ | H2: COSTO | I2: HH Propia | J2: IMPREVISTOS | K2: UTILIDAD | L2: PERSONAL | N2: =SUM(G:G) -> 233638.8 | P2: =COUNTA(A3:A445) -> 10
A3: 234061A-PTTL-P-2 | B3: Petrotal | C3: 315-2023-064-1 | D3: Servicios de Soporte Técnico Especializado del Sistema de Control, Automatización y Almacenamiento | E3: 46023 | F3: 46081 | G3: 32050 | H3: =7960 -> 7960 | I3: 20075 | J3: 0 | K3: 4015 | L3: Eduardo | M3: Empresa | N3: Monto O/C | O3: Empresa | P3: Total
A4: 264004A-VALP-S | B4: Valero | D4: Actualización de Arquitectura de Red de Control y Memoria Descriptiva 2026 | E4: 46062 | F4: 46073 | G4: 2220 | H4: 420 | I4: 1500 | J4: 0 | K4: 300 | L4: Eduardo | M4: Petrotal | N4: =SUMIF(B:B,"petrotal",G:G) -> 197050 | O4: Resertec | P4: =COUNTIF(B:B,"RESERTEC") -> 0
A5: 264005A-TDP-S | B5: Termnales | C5: 34921 | D5: Programación y Visualización de señales de alarmas | E5: 46066 | F5: 46087 | G5: 3380 | H5: 1100 | I5: 1900 | J5: 0 | K5: 380 | L5: Luisa | M5: Resertec | N5: =SUMIF(B:B,"resertec",G:G) -> 0 | O5: TDP | P5: =COUNTIF(B:B,"terminales del perú") -> 0
A6: 264002C-PTTL-P | B6: Petrotal | D6: Ampliación por un año | E6: 46082 | F6: 46387 | G6: 165000 | H6: 36668.33 | I6: 107675 | J6: 0 | K6: 21656.67 | L6: Eduardo | M6: Valero | N6: =SUMIF(B:B,"valero",G:G) -> 9120 | O6: Valero | P6: =COUNTIF(B:B,"valero") -> 4
A7: 264010B-TDP-S | B7: Termnales | D7: Creación de nuevas operaciones en PLC | E7: 46093 | F7: 46099 | G7: 2240 | H7: 800 | I7: 1200 | J7: 0 | K7: 240 | L7: Eduardo | M7: TDP | N7: =SUMIF(B:B,"terminales del perú",G:G) -> 0 | O7: Linde | P7: =COUNTIF(B:B,"Linde") -> 0
A8: 264011A-VALP-S | B8: Valero | D8: Actualización de planos del TCOM 2 y TCOM 3 | E8: 46094 | F8: 46108 | G8: 2400 | H8: 1250 | I8: 970 | J8: 0 | K8: 180 | L8: Eduardo | M8: Linde | N8: =SUMIF(B:B,"linde",G:G) -> 0 | O8: Petrotal | P8: =COUNTIF(B:B,"petrotal") -> 2
A9: 264017A-VALP-S | B9: Valero | D9: INTEGRACIÓN TANQUE B2 - SCADA | E9: 46171 | F9: 46176 | G9: 1420 | H9: 340 | I9: 900 | J9: 0 | K9: 180 | L9: Claudia | M9: Precisión | N9: =SUMIF(B:B,"precisión",G:G) -> 0 | O9: Precisión | P9: =COUNTIF(B:B,"precisión") -> 0
A10: 264018A-TDP-S | B10: Termnales | D10: Cambio de configuración de bombas de Diesel. | E10: 46182 | F10: 46183 | G10: 572 | H10: 212 | I10: 300 | J10: 0 | K10: 60 | L10: Eduardo | M10: Metso | N10: =SUMIF(B:B,"metso",G:G) -> 0 | O10: Metso | P10: =COUNTIF(B:B,"metso") -> 0
A11: 264016B-SERTECPET-S | B11: Sertecpet | D11: Servicio de programación del Sistema de BPCS y SSS L2 EXTENDIDO DEL CAMPO BRETAÑA NORTE - Primera etapa (1-5) | E11: 46199 | F11: 46108 | G11: 21276.8 | H11: 1896.8 | I11: 17100 | J11: 0 | K11: 2280 | L11: Claudia | M11: Confipetrol | N11: =SUMIF(B:B,"confipetrol",G:G) -> 0 | O11: Confipetrol | P11: =COUNTIF(B:B,"confipetrol") -> 0
A12: 264021A-VALP-S | B12: Valero | D12: Integración de PTARI al SCADA. | E12: 46217 | F12: 46234 | G12: 3080 | H12: 560 | I12: 2100 | J12: 0 | K12: 420 | L12: Eduardo | M12: Zeusol | N12: =SUMIF(B:B,"Zeusol",G:G) -> 0 | O12: Zeusol | P12: =COUNTIF(B:B,"zeusol") -> 0
M13: Andalucita | N13: =SUMIF(B:B,"andalucita",G:G) -> 0 | O13: Enaex | P13: =COUNTIF(B:B,"enaex") -> 0
M14: Barrick | N14: =SUMIF(B:B,"Barrick",G:G) -> 0 | O14: Nexa | P14: =COUNTIF(B:B,"nexa") -> 0
M15: Praxair | N15: =SUMIF(B:B,"Praxair",G:G) -> 0 | O15: Savia | P15: =COUNTIF(B:B,"savia") -> 0
M16: Nexa | N16: =SUMIF(B:B,"Nexa",G:G) -> 0 | O16: Barrick | P16: =COUNTIF(B:B,"Barrick") -> 0
M17: Enaex | N17: =SUMIF(B:B,"enaex",G:G) -> 0 | O17: Praxair | P17: =COUNTIF(B:B,"Praxair") -> 0
M18: Savia | N18: =SUMIF(B:B,"savia",G:G) -> 0 | O18: La Arena | P18: =COUNTIF(B:B,"La Arena") -> 0
M19: La Arena | N19: =SUMIF(B:B,"La Arena",G:G) -> 0 | O19: Engie | P19: =COUNTIF(B:B,"engie") -> 0
M20: Simsa | N20: =SUMIF(B:B,"simsa",G:G) -> 0 | O20: James | P20: =COUNTIF(B:B,"james") -> 0
M21: James | N21: =SUMIF(B:B,"james",G:G) -> 0 | O21: Andalucita | P21: =COUNTIF(B:B,"andalucita") -> 0
M22: Engie | N22: =SUMIF(B:B,"engie",G:G) -> 0 | O22: Simsa | P22: =COUNTIF(B:B,"simsa") -> 0
M25: Monto total | N25: =SUM(N4:N24) -> 206170 | P25: =SUM(P4:P24) -> 6
N27: Concepto | O27: Monto
N28: costo | O28: =SUM(H:H) -> 51207.13
N29: HH Propia | O29: =SUM(I:I) -> 153720
N30: Imprevisto | O30: =SUM(J:J) -> 0
N31: Utilidad | O31: =SUM(K:K) -> 29711.67
O32: =SUM(O28:O31) -> 234638.8
N40: HH otras Areas | O40: =P58 -> 0
N42: KPI OIL | O42: =O29+O31 -> 183431.67
N43: =NOW() -> 46237.384
N45: Detalle HH otras Areas
N46: Proyecto | O46: Detalle | P46: HH
N47: 162147B-MMG-S | O47: soporte las bambas
P58: =SUM(P47:P57) -> 0

Sheet IND
A1: ORDENES DE COMPRA INDUSTRIA
A2: CÓDIGO | B2: CLIENTES | C2: N° Orden | D2: PROYECTO | E2: FECHA O/C | F2: FECHA ENTREGA | G2: VALOR PRESUPUESTO $ | H2: COSTO | I2: HH Propia | J2: IMPREVISTOS | K2: UTILIDAD | L2: PERSONAL | N2: =SUM(G:G) -> 58230.19 | Q2: =COUNTA(A3:A450) -> 13
A3: 261002A-RINTI-S | B3: Rinti | C3: 278386940 | D3: Temperatura silos 4000 | E3: 46010 | F3: 46022 | G3: 3300 | H3: 420 | I3: 2400 | J3: 0 | K3: 480 | L3: Luisa | M3: Empresa | N3: Monto O/C | P3: Empresa | Q3: Cantidad
A4: 261007A-RINTI-V | B4: Rinti | C4: OPC2026-285410551 | D4: Canfield Connector Reed switch | E4: 46030 | F4: 46062 | G4: 532.5 | H4: 471 | I4: 0 | J4: 0 | K4: 61.5 | L4: Claudia | M4: Mondelez | N4: =SUMIF(B:B,"Mondelez",G:G) -> 28020.05 | P4: Mondelez | Q4: =COUNTIF(B:B,"Mondelez") -> 3
A5: 251104B-TRUPAL-S | B5: trupal | C5: 4602052586 | D5: Servicio de emergencia - Drive PF trupal Trujillo | E5: 46043 | F5: 46044 | G5: 366 | H5: =168+165 -> 333 | I5: 0 | J5: 0 | K5: 33 | L5: eduardo | M5: KCCP | N5: =SUMIF(B:B,"Kimberly",G:G) -> 0 | P5: Kimberly | Q5: =COUNTIF(B:B,"Kimberly") -> 0
A6: 261009A-NESTLE-S | B6: Nestle | C6: 4580571581 | D6: Modificación SCADA para visualización sensores de Gas | E6: 46045 | F6: 46050 | G6: 1664.64 | H6: 700 | I6: 803.88 | J6: 0 | K6: 160.76 | L6: eduardo | M6: Selim | N6: =SUMIF(B:B,"selim",G:G) -> 0 | P6: Selim | Q6: =COUNTIF(B:B,"selim") -> 0
A7: 251121A-MDZ-V | B7: Mondelez | C7: 7333011639 | D7: Suministro de licencias SQL | E7: 46058 | F7: 46064 | G7: 4073.75 | H7: 2889.9 | I7: 0 | J7: 0 | K7: 1183.85 | L7: eduardo | M7: Peru Process | N7: =SUMIF(B:B,"peru process",G:G) -> 0 | P7: Gloria | Q7: =COUNTIF(B:B,"Gloria") -> 0
A8: 261011A-NESTLE-S | B8: Nestle | C8: 4580661549 | D8: Revisión del PLC de los sensores de amoniaco | E8: 46058 | F8: 46062 | G8: 420 | H8: 120 | I8: 250 | J8: 0 | K8: 50 | L8: eduardo | M8: Gloria | N8: =SUMIF(B:B,"gloria",G:G) -> 0 | P8: Peru Process | Q8: =COUNTIF(B:B,"peru process") -> 0
A9: 261018A-MDZ-S | B9: Mondelez | C9: 7333061880 | D9: CONFIGURACION DE RED INDUSTRIAL L5 | E9: 46073 | F9: 46112 | G9: 13946.3 | H9: 5870 | I9: 7341.9 | J9: 0 | K9: 734.4 | L9: Claudia | M9: Metso | N9: =SUMIF(B:B,"metso",G:G) -> 0 | P9: Dempro | Q9: =COUNTIF(B:B,"dempro") -> 0
A10: 261021A-CSSAA-P | B10: Casa Grande | D10: Servicio de soporte por emergencia PF7000 | E10: 46081 | F10: 46086 | G10: 4616 | H10: =626+3200 -> 3826 | I10: 130 | J10: 0 | K10: 660 | L10: eduardo | M10: Dempro | N10: =SUMIF(B:B,"DEMPRO",G:G) -> 0 | P10: Rinti | Q10: =COUNTIF(B:B,"rinti") -> 4
A11: 261019B-RINTI-S | B11: Rinti | D11: INTEGRACIÓN DE VALVULA DE DISTRIBUIDOR DE MAÍZ (SILO 4000) | E11: 46101 | F11: 46122 | G11: 2180 | H11: 380 | I11: 1500 | J11: 0 | K11: 300 | L11: Claudia | M11: Rinti | N11: =SUMIF(B:B,"Rinti",G:G) -> 9467.5 | P11: Metso | Q11: =COUNTIF(B:B,"metso") -> 0
A12: 261028B-MDZ-S | B12: Mondelez | C12: 7333101068 | D12: Migración de Switches Strarix 5700 a Stratix 5200 - L5 | E12: 46119 | F12: 46149 | G12: 10000 | H12: 6890 | I12: 2825 | J12: 0 | K12: 285 | L12: Claudia | M12: Rockwell | N12: =SUMIF(B:B,"Rockwell",G:G) -> 0 | P12: Rockwell | Q12: =COUNTIF(B:B,"Rockwell") -> 0
A13: 261032A-NESTLE-S | B13: Nestle | C13: 4581800203 | D13: Parada de compresores Sala Vilter con sensor de amoniaco | E13: 46188 | F13: 46198 | G13: 880 | H13: 160 | I13: 600 | J13: 0 | K13: 120 | L13: Claudia | M13: Molitalia | N13: =SUMIF(B:B,"molitalia",G:G) -> 0 | P13: CONNECT TECH | Q13: =COUNTIF(B:B,"CONNECT TECH") -> 0
A14: 261037B-RINTI-S | B14: Rinti | D14: Actualización de Filosofía de Control de Multipartículas 2 | E14: 46213 | F14: 46230 | G14: 3455 | H14: =506.96+400 -> 906.96 | I14: 2060 | J14: 0 | K14: 488.04 | L14: eduardo | M14: Eternit | N14: =SUMIF(B:B,"eternit",G:G) -> 0 | P14: SC ING | Q14: =COUNTIF(B:B,"SC ing.") -> 0
A15: 261025C-NESTLE-S | B15: Nestle | C15: 4582046265 | D15: Automatización de cambio de agua de desmolde de bombones | E15: 46217 | F15: 46300 | G15: 12796 | H15: =1762+5650 -> 7412 | I15: 4293 | J15: 0 | K15: 1091 | L15: Claudia | M15: Bradjur | N15: =SUMIF(B:B,"bradjur",G:G) -> 0 | P15: Molitalia | Q15: =COUNTIF(B:B,"molitalia") -> 0
M16: Global Alimentos | N16: =SUMIF(B:B,"global alimentos",G:G) -> 0 | P16: Eternit | Q16: =COUNTIF(B:B,"Eternit") -> 0
M17: CONNECT TECH | N17: =SUMIF(B:B,"CONNECT TECH",G:G) -> 0 | P17: Global Alimentos | Q17: =COUNTIF(B:B,"global alimentos") -> 0
M18: OI | N18: =SUMIF(B:B,"Owens illinois",G:G) -> 0 | P18: Precisión | Q18: =COUNTIF(B:B,"Precisión") -> 0
M19: Precisión | N19: =SUMIF(B:B,"Precisión",G:G) -> 0 | P19: Bimbo | Q19: =COUNTIF(B:B,"Bimbo") -> 0
M20: Bimbo | N20: =SUMIF(B:B,"bimbo",G:G) -> 0 | P20: GoodYear | Q20: =COUNTIF(B:B,"Goodyear") -> 0
M21: GoodYear | N21: =SUMIF(B:B,"GoodYear",G:G) -> 0 | P21: OI | Q21: =COUNTIF(B:B,"Owens Illinois") -> 0
M23: Monto Total | N23: =SUM(N4:N22) -> 37487.55 | O23: =O29-N23 -> 20742.64 | Q23: =SUM(Q4:Q22) -> 7
N24: Concepto | O24: Monto
N25: costo | O25: =SUM(H:H) -> 30378.86
N26: HH Propia | O26: =SUM(I:I) -> 22203.78
N27: Imprevisto | O27: =SUM(J:J) -> 0
N28: Utilidad | O28: =SUM(K:K) -> 5647.55
O29: =SUM(O25:O28) -> 58230.19
N32: Por Facturar | O32: =SUM(#REF!) -> #REF!
N33: Facturado | O33: =SUM(#REF!) -> #REF!
O34: =SUM(O32:O33) -> #REF!
N36: HH otras Areas | O36: =P56 -> 0
N39: KPI IND | O39: =O26+O28 -> 27851.33
N40: =NOW() -> 46237.384 | R40: Tipo | S40: Monto
R41: Venta | S41: 0
N42: Detalle HH otras Areas | R42: Servicio y Proyectos | S42: =O29 -> 58230.19
N43: Proyecto | O43: Detalle | P43: HH
P56: =SUM(P44:P55) -> 0

Sheet SFY
A1: ORDENES DE COMPRA SAFETY
A2: CÓDIGO | B2: CLIENTES | C2: N° Orden | D2: PROYECTO | E2: FECHA O/C | F2: FECHA ENTREGA | G2: VALOR PRESUPUESTO $ | H2: COSTO | I2: HH Propia | J2: IMPREVISTOS | K2: UTILIDAD | L2: Comentario | N2: =SUM(G:G) -> 0 | P2: =COUNTA(A3:A438) -> 0
M3: Empresa | N3: Monto | O3: Empresa | P3: Cantidad
M4: Abboott | N4: =SUMIF(B:B,"abbott",G:G) -> 0 | O4: Copeinca | P4: =COUNTIF(B:B,"copeinca") -> 0
M5: Copeinca | N5: =SUMIF(B:B,"copeinca",G:G) -> 0 | O5: Savia | P5: =COUNTIF(B:B,"savia") -> 0
M6: Savia | N6: =SUMIF(B:B,"Savia",G:G) -> 0 | O6: APM | P6: =COUNTIF(B:B,"apm terminals") -> 0
M7: Mondelez | N7: =SUMIF(B:B,"Mondelez",G:G) -> 0 | O7: Mondelez | P7: =COUNTIF(B:B,"Mondelez") -> 0
M8: Forsac | N8: =SUMIF(B:B,"forsac",G:G) -> 0 | O8: Nexa | P8: =COUNTIF(B:B,"nexa") -> 0
M9: Nexa | N9: =SUMIF(B:B,"nexa",G:G) -> 0 | O9: Forsac | P9: =COUNTIF(B:B,"forsac") -> 0
M10: S&P | N10: =SUMIF(B:B,"solier&palao",G:G) -> 0 | O10: Eternit | P10: =COUNTIF(B:B,"eternit") -> 0
M11: Eternit | N11: =SUMIF(B:B,"eternit",G:G) -> 0 | O11: S&P | P11: =COUNTIF(B:B,"solier&palao") -> 0
M13: Monto Total | N13: =SUM(N4:N12) -> 0 | P13: =SUM(P4:P12) -> 0
N15: Concepto | O15: Monto
N16: costo | O16: =SUM(H:H) -> 0
N17: HH Propia | O17: =SUM(I:I) -> 0
N18: Imprevisto | O18: =SUM(J:J) -> 0
N19: Utilidad | O19: =SUM(K:K) -> 0
O20: =SUM(O16:O19) -> 0
N22: Por Facturar | O22: =SUM(#REF!) -> #REF!
N23: Facturado | O23: =SUM(#REF!) -> #REF!
O24: =O22+O23 -> #REF!
N26: HH otras Areas
N28: KPI SFY | O28: =O17+O19 -> 0
N29: =NOW() -> 46237.384
N31: Detalle HH otras Areas
N32: Proyecto | O32: Detalle | P32: HH | Q32: ÁREA | R32: ESTADO (PENDIENTE, PARCIAL O EJECUTADO )
R33: No Ejecutado
R34: No Ejecutado
R35: No Ejecutado
R36: No Ejecutado
R37: No Ejecutado
R38: No Ejecutado
R39: No Ejecutado
R40: No Ejecutado
R41: No Ejecutado
P78: =SUM(P33:P77) -> 0

Sheet  2011-2026
A1: Gerencia | B1: Monto OC | C1: Cantidad
A2: IND | B2: =IND!N2 -> 58230.19 | C2: =IND!Q2 -> 13 | E2: Año | F2: Montos OC | G2: HH+Utilidad | H2: Objetivo Min | I2: Cantidad
A3: MIN | B3: =MIN!N2 -> 1144091.1 | C3: =MIN!P2 -> 31 | E3: 2012 | F3: 856894.56 | G3: 0 | I3: 132
A4: OIL | B4: =OIL!N2 -> 233638.8 | C4: =OIL!P2 -> 10 | E4: 2013 | F4: 1173006.5 | G4: 0 | I4: 172
A5: SFY | B5: =SFY!N2 -> 0 | C5: =SFY!P2 -> 0 | E5: 2014 | F5: 1469563.6 | G5: 766989.82 | H5: 599213.69 | I5: 198
A6: Total | B6: =SUM(B2:B5) -> 1435960.1 | C6: =SUM(C2:C5) -> 54 | E6: 2015 | F6: 1886500 | G6: 732610.43 | H6: 791852.48 | I6: 281
E7: 2016 | F7: 1143432.9 | G7: =Objetivos!N4 -> 546600.85 | H7: 791852.48 | I7: 142
E8: 2017 | F8: 1755581.9 | G8: =Objetivos!N5 -> 586456.22 | H8: 786394.2 | I8: 164
E9: 2018 | F9: 2040281 | G9: =Objetivos!N6 -> 815521.11 | H9: 1015424.4 | I9: 184
E10: 2019 | F10: 2650233.1 | G10: 706732.22 | H10: 1016302.2 | I10: 188
E11: 2020 | F11: 1732121.3 | G11: 820464.89 | H11: 869409.41 | I11: 106
E12: 2021 | F12: 1434996.9 | G12: 475934.45 | H12: 864817.23 | I12: 120
E13: 2022 | F13: 1968764 | G13: 764082.81 | H13: 726996.85 | I13: 99
E14: 2023 | F14: 1676545.4 | G14: 832552.59 | H14: 872396.23 | I14: 101
E15: 2024 | F15: 1697269.4 | G15: 865726.08 | H15: 1046875.5 | I15: 111
E16: 2025 | F16: 1683042 | G16: 787520.06 | H16: 1046875.5 | I16: 90
E17: 2026 | F17: =B6 -> 1435960.1 | G17: =Objetivos!N14 -> 647191.24 | H17: =Objetivos!C6 -> 1165000 | I17: =C6 -> 54
A37: Industria
A38: Año | B38: ENE | C38: FEB | D38: MAR | E38: ABR | F38: MAY | G38: JUN | H38: JUL | I38: AGO | J38: SEP | K38: OCT | L38: NOV | M38: DIC | N38: Total
A39: 2011 | B39: 0 | C39: 0 | D39: 8081.84 | E39: 1225.4545 | F39: 0 | G39: 1996 | H39: 840.55 | I39: 34797.82 | J39: 0 | K39: 111991.51 | L39: 6400 | M39: 9116.67 | N39: =SUM(B39:H39) -> 12143.845
A40: 2012 | B40: 288.75 | C40: 16966.01 | D40: 11996.84 | E40: 10473.8 | F40: 23696.62 | G40: 17358.2 | H40: 11531.73 | I40: 11142.81 | J40: 3372.72 | K40: 370.5 | L40: 38269.66 | M40: 20800.84 | N40: =SUM(B40:H40) -> 92311.95
A41: 2013 | B41: 14551.34 | C41: 19427.05 | D41: 2262 | E41: 39092.38 | F41: 31540.28 | G41: 19834.15 | H41: 3903.08 | I41: 49596.05 | J41: 11850.33 | K41: 28657.57 | L41: 34503.31 | M41: 0 | N41: =SUM(B41:H41) -> 130610.28
A42: 2014 | B42: 35533.57 | C42: 3500 | D42: 13796 | E42: 6360 | F42: 34670 | G42: 20700 | H42: 27649.9 | I42: 12924.2 | J42: 71445.26 | K42: 125296.03 | L42: 19935.01 | M42: 19950 | N42: =SUM(B42:H42) -> 142209.47
A43: 2015 | B43: 350 | C43: 520 | D43: 48338.97 | E43: 1619.9 | F43: 400 | G43: 55726.74 | H43: 11186.8 | I43: 32656.2 | J43: 40006.2 | K43: 7070.13 | L43: 12900 | M43: 59189 | N43: =SUM(B43:H43) -> 118142.41
A44: 2016 | B44: 72001.95 | C44: 91133.37 | D44: 28155.6 | E44: 1222.5 | F44: 600 | G44: 3688.4 | H44: 28031.2 | I44: 15845.01 | J44: 4185.51 | K44: 12128.1 | L44: 3607.08 | M44: 0 | N44: =SUM(B44:H44) -> 224833.02
A45: 2017 | B45: 64761.73 | C45: 133870.17 | D45: 24456.54 | E45: 1982 | F45: 41474 | G45: 5605.16 | H45: 154797.51 | I45: 147549.01 | J45: 8547.44 | K45: 2414.93 | L45: 65263.49 | M45: 4153.44 | N45: =SUM(B45:H45) -> 426947.11
A46: 2018 | B46: 52182.85 | C46: 49954.11 | D46: 58985.66 | E46: 22090.56 | F46: 142594.25 | G46: 5134 | H46: 2000.7 | I46: 17059.71 | J46: 18400 | K46: 10400 | L46: 88735.85 | M46: 6490.22 | N46: =SUM(B46:H46) -> 332942.13
A47: 2019 | B47: 11400.28 | C47: 9990 | D47: 0 | E47: 2682.46 | F47: 95953.7 | G47: 22179.66 | H47: 0 | I47: 9915.6 | J47: 800 | K47: 850 | L47: 11491.8 | M47: 0 | N47: =SUM(B47:H47) -> 142206.1
A48: 2020 | B48: 23660.59 | C48: 33033.16 | D48: 0 | E48: 0 | F48: 0 | G48: 0 | H48: 16924.46 | I48: 110 | J48: 1354.46 | K48: 1452.34 | L48: 3544.38 | M48: 0 | N48: =SUM(B48:H48) -> 73618.21
A49: 2021 | B49: 23852.65 | C49: 0 | D49: 1104.57 | E49: 4337.71 | F49: 0 | G49: 0 | H49: 155 | I49: 203786.44 | J49: 127.78 | K49: 7402.35 | L49: 2438 | M49: 14071 | N49: =SUM(B49:H49) -> 29449.93
A50: 2022 | B50: 0 | C50: 1801.81 | D50: 6522.74 | E50: 10289.54 | F50: 471.6 | G50: 14709 | H50: 0 | I50: 9710 | J50: 100 | K50: 17001.24 | L50: 1255 | M50: 0 | N50: =SUM(B50:H50) -> 33794.69
A51: 2023 | B51: 200 | C51: 67062.29 | D51: 0 | E51: 0 | F51: 0 | G51: 0 | H51: 0 | I51: 4038.44 | J51: 0 | K51: 12265 | L51: 6952.98 | N51: =SUM(B51:H51) -> 67262.29
A52: 2024 | B52: 4488.68 | C52: 71868.06 | D52: 18225.89 | E52: 15772.49 | F52: 2420 | G52: 9325 | H52: 80 | I52: 0 | J52: 7716.63 | K52: 83007.03 | L52: 27973.71 | M52: 50418.03 | N52: =SUM(B52:H52) -> 122180.12
A53: 2025 | B53: 22486.11 | C53: 16355 | D53: 21167.93 | E53: 2998.89 | F53: 3408 | G53: 12106.81 | H53: 3745 | I53: 10726.67 | J53: 13640.04 | K53: 9276.19 | L53: 4000.64 | M53: 4604.6 | N53: =SUM(B53:H53) -> 82267.74
A54: 2026 | B54: 5863.14 | C54: 23056.05 | D54: 2180 | E54: 10000 | F54: 0 | G54: 880 | H54: 16251 | N54: =SUM(B54:H54) -> 58230.19
A82: Minería
B83: ENE | C83: FEB | D83: MAR | E83: ABR | F83: MAY | G83: JUN | H83: JUL | I83: AGO | J83: SEP | K83: OCT | L83: NOV | M83: DIC | N83: Total
A84: 2011 | B84: 0 | C84: 0 | D84: 143668.9 | E84: 46280.65 | F84: 11504.24 | G84: 93709.46 | H84: 0 | I84: 41411.92 | J84: 22074.98 | K84: 51330.95 | L84: 10405 | M84: 78179.6 | N84: =SUM(B84:H84) -> 295163.25
A85: 2012 | B85: 6016.7 | C85: 0 | D85: 272173.48 | E85: 9853.12 | F85: 13313.7 | G85: 8315.85 | H85: 9464.65 | I85: 2110.4 | J85: 2368 | K85: 0 | L85: 9172.15 | M85: 12995.65 | N85: =SUM(B85:H85) -> 319137.5
A86: 2013 | B86: 9000 | C86: 6885 | D86: 222917.66 | E86: 59817.55 | F86: 394.4 | G86: 24251.24 | H86: 3454.21 | I86: 39736.85 | J86: 245081.41 | K86: 6332.89 | L86: 15281.25 | M86: 19860 | N86: =SUM(B86:H86) -> 326720.06
...

Sheet Objetivos
B1: OBJETIVO ANUAL MÁXIMO | C1: OBJETIVO ANUAL MÍNIMO | D1: LOGRADO | E1: OBJETIVO MÁX AL MES | F1: OBJETIVO MÍN AL MES | G1: DIFERENCIA CONSEGUIDO C/ MÍNIMO | H1: DIFERENCIA CONSEGUIDO C/ MÁXIMO | I1: FALTANTE AL MÍNIMO | J1: FALTANTE AL MÁXIMO | M1: Logrado | N1: Monto
A2: MIN | B2: 625000 | C2: 615000 | D2: =MIN!O39 -> 435908.24 | E2: =B2/12*8 -> 416666.67 | F2: =C2/12*8 -> 410000 | G2: =D2-F2 -> 25908.24 | H2: =D2-E2 -> 19241.573 | I2: =D2-C2 -> -179091.76 | J2: =D2-B2 -> -189091.76 | M2: 2014 | N2: 599213.69
A3: IND | B3: 260000 | C3: 250000 | D3: =IND!O39 -> 27851.33 | E3: =B3/12*8 -> 173333.33 | F3: =C3/12*8 -> 166666.67 | G3: =D3-F3 -> -138815.34 | H3: =D3-E3 -> -145482 | I3: =D3-C3 -> -222148.67 | J3: =D3-B3 -> -232148.67 | M3: 2015 | N3: 791852.48
A4: OIL | B4: 230000 | C4: 220000 | D4: =OIL!O42 -> 183431.67 | E4: =B4/12*8 -> 153333.33 | F4: =C4/12*8 -> 146666.67 | G4: =D4-F4 -> 36765.003 | H4: =D4-E4 -> 30098.337 | I4: =D4-C4 -> -36568.33 | J4: =D4-B4 -> -46568.33 | M4: 2016 | N4: 546600.85
A5: SFY | B5: 90000 | C5: 80000 | D5: =SFY!O28 -> 0 | E5: =B5/12*8 -> 60000 | F5: =C5/12*8 -> 53333.333 | G5: =D5-F5 -> -53333.333 | H5: =D5-E5 -> -60000 | I5: =D5-C5 -> -80000 | J5: =D5-B5 -> -90000 | M5: 2017 | N5: 586456.22
A6: TOTALES | B6: =SUM(B2:B5) -> 1205000 | C6: =SUM(C2:C5) -> 1165000 | D6: =SUM(D2:D5) -> 647191.24 | E6: =SUM(E2:E5) -> 803333.33 | F6: =SUM(F2:F5) -> 776666.67 | G6: =D6-F6 -> -129475.43 | H6: =D6-E6 -> -156142.09 | I6: =D6-C6 -> -517808.76 | J6: =D6-B6 -> -557808.76 | M6: 2018 | N6: 815521.11
M7: 2019 | N7: 706732.22
C8: Faltante al Min | D8: =C6-D6 -> 517808.76 | M8: 2020 | N8: 820464.89
C9: Faltante al Max | D9: =B6-D6 -> 557808.76 | M9: 2021 | N9: 475934.45
M10: 2022 | N10: 764082.81
M11: 2023 | N11: 832552.59
M12: 2024 | N12: 865726.08
M13: 2025 | N13: 787520.06
M14: 2026 | N14: =D6 -> 647191.24
G17: =SUM(MIN!I:I)+SUM(MIN!K:K) -> 435908.24 | H17: =SUM(MIN!I:I)+SUM(MIN!K:K) -> 435908.24
B18: Maximo | D18: Mínimo | G18: =SUM(IND!I:I)+SUM(IND!K:K) -> 27851.33 | H18: =SUM(IND!I:I)+SUM(IND!K:K) -> 27851.33
B19: Avance | C19: Faltante | D19: Avance | E19: Faltante | G19: =SUM(OIL!I:I)+SUM(OIL!K:K) -> 183431.67 | H19: =SUM(OIL!I:I)+SUM(OIL!K:K) -> 183431.67
A20: MIN | B20: =(D2*100/E2)% -> 1.0461798 | C20: 0 | D20: =(D2*100/F2)% -> 1.0631908 | E20: 0 | G20: =SUM(SFY!I:I)+SUM(SFY!K:K) -> 0 | H20: =SUM(SFY!I:I)+SUM(SFY!K:K) -> 0
A21: IND | B21: =(D3*100/E3)% -> 0.16068075 | C21: =100%-B21 -> 0.83931925 | D21: =(D3*100/F3)% -> 0.16710798 | E21: =100%-D21 -> 0.83289202 | G21: =SUM(G17:G20) -> 647191.24 | H21: =SUM(H17:H20) -> 647191.24
A22: OIL | B22: =(D4*100/E4)% -> 1.1962935 | C22: 0 | D22: =(D4*100/F4)% -> 1.2506705 | E22: 0
A23: SFY | B23: =(D5*100/E5)% -> 0 | C23: =100%-B23 -> 1 | D23: =(D5*100/F5)% -> 0 | E23: =100%-D23 -> 1
A24: V&C | B24: =(D6*100/E6)% -> 0.80563225 | C24: =100%-B24 -> 0.19436775 | D24: =(D6*100/F6)% -> 0.83329344 | E24: =100%-D24 -> 0.16670656
B51: Porcentaje | C51: Escala
B52: 0.1 | C52: 1
B53: 0.2 | C53: 1
B54: 0.3 | C54: 1
B55: 0.4 | C55: 1
B56: 0.5 | C56: 1
B57: 0.6 | C57: 1
B58: 0.7 | C58: 1
B59: 0.8 | C59: 1
B60: 0.9 | C60: 1
B61: 1 | C61: =SUM(C52:C60) -> 9
B63: Grado MIN | C63: =G66*PI() -> 1.7452457
B64: Grado MX | C64: =G67*PI() -> 1.6873122
B65: Puntos | C65: X | D65: Y
B66: Inicio | C66: 0 | D66: 0 | F66: Avance MIN | G66: =D6*100%/C6 -> 0.55552896 | H66: 56
B67: Fin | C67: =COS(C63)*-1 -> 0.1735659 | D67: =SIN(C63) -> 0.98482226 | F67: Avance MAX | G67: =D6*100%/B6 -> 0.53708817 | H67: 54
B69: Puntos | C69: X | D69: Y
B70: Inicio | C70: 0 | D70: 0
...

Sheet Objetivos Com.
C1: MAX | D1: MIN | E1: PRO. TRA. | F1: Obj. Max | G1: Obj. Min | H1: Conseguido | I1: % Max | J1: % Min
A2: COM | B2: Juan José Castillo M. | C2: 105014.9 | E2: 0.2 | F2: =C2*E2 -> 21002.98 | G2: =C2*E2 -> 21002.98 | H2: =SUMIF(MIN!L:L,"Juan José Castillo",MIN!I:I)+SUMIF(MIN!L:L,"Juan José Castillo",MIN!K:K) -> 0 | I2: =(H2*100/F2)% -> 0 | J2: =(H2*100/G2)% -> 0
B3: Eduardo Bonilla | E3: 0.2 | F3: =C2*E3 -> 21002.98 | G3: =C2*E3 -> 21002.98 | H3: =SUMIF(MIN!L:L,"Eduardo Bonilla",MIN!I:I)+SUMIF(MIN!L:L,"Eduardo Bonilla",MIN!K:K) -> 0 | I3: =(H3*100/F3)% -> 0 | J3: =(H3*100/G3)% -> 0
B4: Juan Pablo Flores | E4: 0.2 | F4: =C2*E4 -> 21002.98 | G4: =C2*E4 -> 21002.98 | H4: =SUMIF(MIN!L:L,"Juan Flores",MIN!I:I)+SUMIF(MIN!L:L,"Juan Flores",MIN!K:K) -> 0 | I4: =(H4*100/F4)% -> 0 | J4: =(H4*100/G4)% -> 0
B5: Luisa Oncebay | E5: 0.2 | F5: =C2*E5 -> 21002.98 | G5: =C2*E5 -> 21002.98 | H5: =SUMIF(MIN!L:L,"Luisa Oncevay",MIN!I:I)+SUMIF(MIN!L:L,"Luisa Oncevay",MIN!K:K) -> 0 | I5: =(H5*100/F5)% -> 0 | J5: =(H5*100/G5)% -> 0
B6: Heberth Martinez | E6: 0.2 | F6: =C2*E6 -> 21002.98 | G6: =C2*E6 -> 21002.98 | H6: =SUMIF(MIN!L:L,"Heberth Martinez",MIN!I:I)+SUMIF(MIN!L:L,"Heberth Martinez",MIN!K:K) -> 0 | I6: =(H6*100/F6)% -> 0 | J6: =(H6*100/G6)% -> 0
E7: =SUM(E2:E6) -> 1 | F7: =SUM(F2:F6) -> 105014.9 | G7: =SUM(G2:G6) -> 105014.9 | H7: =SUM(H2:H6) -> 0
C10: MAX | D10: MIN | E10: PRO. TRA. | F10: Obj. Max | G10: Obj. Min | H10: Conseguido | I10: % Max | J10: % Min
A11: COM | B11: Juan José Castillo M. | C11: 105014.9 | E11: 0.2 | F11: =C11*E11 -> 21002.98 | G11: =C11*E11 -> 21002.98 | H11: =SUMIF(IND!L:L,"Juan José Castillo",IND!I:I)+SUMIF(IND!L:L,"Juan José Castillo",IND!K:K) -> 0 | I11: =(H11*100/F11)% -> 0 | J11: =(H11*100/G11)% -> 0
B12: Eduardo Bonilla | E12: 0.2 | F12: =C11*E12 -> 21002.98 | G12: =C11*E12 -> 21002.98 | H12: =SUMIF(IND!L:L,"Eduardo Bonilla",IND!I:I)+SUMIF(IND!L:L,"Eduardo Bonilla",IND!K:K) -> 0 | I12: =(H12*100/F12)% -> 0 | J12: =(H12*100/G12)% -> 0
B13: Juan Pablo Flores | E13: 0.2 | F13: =C11*E13 -> 21002.98 | G13: =C11*E13 -> 21002.98 | H13: =SUMIF(IND!L:L,"Juan Flores",IND!I:I)+SUMIF(IND!L:L,"Juan Flores",IND!K:K) -> 0 | I13: =(H13*100/F13)% -> 0 | J13: =(H13*100/G13)% -> 0
B14: Luisa Oncebay | E14: 0.2 | F14: =C11*E14 -> 21002.98 | G14: =C11*E14 -> 21002.98 | H14: =SUMIF(IND!L:L,"Luisa oncebay",IND!I:I)+SUMIF(IND!L:L,"Luisa oncebay",IND!K:K) -> 0 | I14: =(H14*100/F14)% -> 0 | J14: =(H14*100/G14)% -> 0
B15: Heberth Martinez | E15: 0.2 | F15: =C11*E15 -> 21002.98 | G15: =C11*E15 -> 21002.98 | H15: =SUMIF(IND!L:L,"heberth Martinez",IND!I:I)+SUMIF(IND!L:L,"Heberth Martinez",IND!K:K) -> 0 | I15: =(H15*100/F15)% -> 0 | J15: =(H15*100/G15)% -> 0
E16: =SUM(E11:E15) -> 1 | F16: =SUM(F11:F15) -> 105014.9 | G16: =SUM(G11:G15) -> 105014.9 | H16: =SUM(H11:H15) -> 0
C19: MAX | D19: MIN | E19: PRO. TRA. | F19: Obj. Max | G19: Obj. Min | H19: Conseguido | I19: % Max | J19: % Min
A20: COM | B20: Juan José Castillo M. | C20: 105014.9 | E20: 0.2 | F20: =C20*E20 -> 21002.98 | G20: =C20*E20 -> 21002.98 | H20: =SUMIF(OIL!L:L,"Juan José Castillo",OIL!I:I)+SUMIF(OIL!L:L,"Juan José Castillo",OIL!K:K) -> 0 | I20: =(H20*100/F20)% -> 0 | J20: =(H20*100/G20)% -> 0
B21: Eduardo Bonilla | E21: 0.2 | F21: =C20*E21 -> 21002.98 | G21: =C20*E21 -> 21002.98 | H21: =SUMIF(OIL!L:L,"Eduardo Bonilla",OIL!I:I)+SUMIF(OIL!L:L,"eduardo bonilla",OIL!K:K) -> 0 | I21: =(H21*100/F21)% -> 0 | J21: =(H21*100/G21)% -> 0
B22: Juan Pablo Flores | E22: 0.2 | F22: =C20*E22 -> 21002.98 | G22: =C20*E22 -> 21002.98 | H22: =SUMIF(OIL!L:L,"juan flores",OIL!I:I)+SUMIF(OIL!L:L,"juan flores",OIL!K:K) -> 0 | I22: =(H22*100/F22)% -> 0 | J22: =(H22*100/G22)% -> 0
B23: Luisa Oncebay | E23: 0.2 | F23: =C20*E23 -> 21002.98 | G23: =C20*E23 -> 21002.98 | H23: =SUMIF(OIL!L:L,"luisa oncebay",OIL!I:I)+SUMIF(OIL!L:L,"luisa oncebay",OIL!K:K) -> 0 | I23: =(H23*100/F23)% -> 0 | J23: =(H23*100/G23)% -> 0
B24: Heberth Martines | E24: 0.2 | F24: =C20*E24 -> 21002.98 | G24: =C20*E24 -> 21002.98 | H24: =SUMIF(OIL!L:L,"Heberth Martinez",OIL!I:I)+SUMIF(OIL!L:L,"Heberth Martinez",OIL!K:K) -> 0 | I24: =(H24*100/F24)% -> 0 | J24: =(H24*100/G24)% -> 0
E25: =SUM(E20:E24) -> 1 | F25: =SUM(F20:F24) -> 105014.9 | G25: =SUM(G20:G24) -> 105014.9 | H25: =SUM(H20:H24) -> 0
C28: MAX | D28: MIN | E28: PRO. TRA. | F28: Obj. Max | G28: Obj. Min | H28: Conseguido | I28: % Max | J28: % Min
A29: COM | B29: Juan José Castillo M. | C29: 105014.9 | E29: 0.2 | F29: =C29*E29 -> 21002.98 | G29: =C29*E29 -> 21002.98 | H29: =SUMIF(SFY!L:L,"Juan José Castillo",SFY!I:I)+SUMIF(SFY!L:L,"Juan José Castillo",SFY!K:K) -> 0 | I29: =(H29*100/F29)% -> 0 | J29: =(H29*100/G29)% -> 0
B30: Eduardo Bonilla | E30: 0.2 | F30: =C29*E30 -> 21002.98 | G30: =C29*E30 -> 21002.98 | H30: =SUMIF(SFY!L:L,"eduardo bonilla",SFY!I:I)+SUMIF(SFY!L:L,"eduardo bonilla",SFY!K:K) -> 0 | I30: =(H30*100/F30)% -> 0 | J30: =(H30*100/G30)% -> 0
B31: Juan Pablo Flores | E31: 0.2 | F31: =C29*E31 -> 21002.98 | G31: =C29*E31 -> 21002.98 | H31: =SUMIF(SFY!L:L,"juan flores",SFY!I:I)+SUMIF(SFY!L:L,"juan flores",SFY!K:K) -> 0 | I31: =(H31*100/F31)% -> 0 | J31: =(H31*100/G31)% -> 0
B32: Luisa Oncebay | E32: 0.2 | F32: =C29*E32 -> 21002.98 | G32: =C29*E32 -> 21002.98 | H32: =SUMIF(SFY!L:L,"luisa oncebay",SFY!I:I)+SUMIF(SFY!L:L,"luisa oncebay",SFY!K:K) -> 0 | I32: =(H32*100/F32)% -> 0 | J32: =(H32*100/G32)% -> 0
B33: Heberth Martinez | E33: 0.2 | F33: =C29*E33 -> 21002.98 | G33: =C29*E33 -> 21002.98 | H33: =SUMIF(SFY!L:L,"Heberth Martinez",SFY!I:I)+SUMIF(SFY!L:L,"Heberth Martinez",SFY!K:K) -> 0 | I33: =(H33*100/F33)% -> 0 | J33: =(H33*100/G33)% -> 0
E34: =SUM(E29:E33) -> 1 | F34: =SUM(F29:F33) -> 105014.9 | G34: =SUM(G29:G33) -> 105014.9 | H34: =SUM(H29:H33) -> 0
B37: Area | C37: Cuota Comercial | D37: Conseguido | E37: %
B38: Minería | C38: =C2 -> 105014.9 | D38: =SUM(H2:H5) -> 0 | E38: =D38*100/C38 -> 0
B39: Industria | C39: =C11 -> 105014.9 | D39: =SUM(H11:H14) -> 0 | E39: =D39*100/C39 -> 0
B40: Petroquímica | C40: =C20 -> 105014.9 | D40: =SUM(H20:H23) -> 0 | E40: =D40*100/C40 -> 0
B41: Safety | C41: =C29 -> 105014.9 | D41: =SUM(H29:H32) -> 0 | E41: =D41*100/C41 -> 0
B42: Total | C42: =SUM(C38:C41) -> 420059.6 | D42: =SUM(D38:D41) -> 0 | E42: =(D42*100)/C42 -> 0
B45: Juan Joosé Castillo | C45: =H2+H11+H20+H29 -> 0
B46: Eduardo Bonilla | C46: =H3+H12+H21+H30 -> 0
B47: Juan Flores | C47: =H4+H13+H22+H31 -> 0
B48: Luisa Oncebay | C48: =H5+H14+H23+H32 -> 0
B49: Heberth Martinez | C49: =H6+H15+H24+H33 -> 0
C50: =SUM(C45:C49) -> 0

Sheet Admin y Com
B1: COMERCIAL | G1: ADMINISTRACIÓN
A2: MES | B2: MIN | C2: IND | D2: OIL | E2: SFY | F2: Monto OC | G2: MIN | H2: IND | I2: OIL | J2: SFY | K2: Monto Fact
A3: Ene | B3: =' 2011-2026'!$M$198 -> 555391.25 | C3: =' 2011-2026'!N198 -> 5863.14 | D3: =' 2011-2026'!O198 -> 32050 | E3: =' 2011-2026'!P198 -> 0 | F3: =SUM(B3:E3) -> 593304.39 | G3: 0 | H3: 0 | I3: 390 | J3: 158050.41 | K3: =SUM(G3:J3) -> 158440.41
A4: Feb | B4: =' 2011-2026'!$M$199 -> 78565.29 | C4: =' 2011-2026'!N199 -> 23056.05 | D4: =' 2011-2026'!O199 -> 5600 | E4: =' 2011-2026'!P199 -> 0 | F4: =SUM(B4:E4) -> 107221.34 | G4: 3992 | H4: 1593.14 | I4: 0 | J4: 0 | K4: =SUM(G4:J4) -> 5585.14
A5: Mar | B5: =' 2011-2026'!$M$200 -> 88547.91 | C5: =' 2011-2026'!N200 -> 2180 | D5: =' 2011-2026'!O200 -> 169640 | E5: =' 2011-2026'!P200 -> 0 | F5: =SUM(B5:E5) -> 260367.91 | G5: 0 | H5: 15865 | I5: 0 | J5: 0 | K5: =SUM(G5:J5) -> 15865
A6: Abr | B6: =' 2011-2026'!$M$201 -> 36334.09 | C6: =' 2011-2026'!N201 -> 10000 | D6: =' 2011-2026'!O201 -> 0 | E6: =' 2011-2026'!P201 -> 0 | F6: =SUM(B6:E6) -> 46334.09 | G6: 0 | H6: 0 | I6: 0 | J6: 0 | K6: =SUM(G6:J6) -> 0
A7: May | B7: =' 2011-2026'!$M$202 -> 45797.8 | C7: =' 2011-2026'!N202 -> 0 | D7: =' 2011-2026'!O202 -> 1420 | E7: =' 2011-2026'!P202 -> 0 | F7: =SUM(B7:E7) -> 47217.8 | G7: 109661.56 | H7: 0 | I7: 0 | J7: 44411.76 | K7: =SUM(G7:J7) -> 154073.32
A8: Jun | B8: =' 2011-2026'!$M$203 -> 66020.17 | C8: =' 2011-2026'!N203 -> 880 | D8: =' 2011-2026'!O203 -> 21848.8 | E8: =' 2011-2026'!P203 -> 0 | F8: =SUM(B8:E8) -> 88748.97 | G8: 59361.33 | H8: 0 | I8: 12158.81 | J8: 26588.24 | K8: =SUM(G8:J8) -> 98108.38
A9: Jul | B9: =' 2011-2026'!$M$204 -> 273434.6 | C9: =' 2011-2026'!N204 -> 16251 | D9: =' 2011-2026'!O204 -> 3080 | E9: =' 2011-2026'!P204 -> 0 | F9: =SUM(B9:E9) -> 292765.6 | G9: 100914.29 | H9: 12300.04 | I9: 84211 | J9: 700 | K9: =SUM(G9:J9) -> 198125.33
A10: Ago | B10: =' 2011-2026'!$M$205 -> 0 | C10: =' 2011-2026'!N205 -> 0 | D10: =' 2011-2026'!O205 -> 0 | E10: =' 2011-2026'!P205 -> 0 | F10: =SUM(B10:E10) -> 0 | G10: 19872.12 | H10: 834.46 | I10: 8214 | J10: 1880 | K10: =SUM(G10:J10) -> 30800.58
A11: Sep | B11: =' 2011-2026'!$M$206 -> 0 | C11: =' 2011-2026'!N206 -> 0 | D11: =' 2011-2026'!O206 -> 0 | E11: =' 2011-2026'!P206 -> 0 | F11: =SUM(B11:E11) -> 0 | G11: 49278.2 | H11: 0 | I11: 0 | J11: 11850.01 | K11: =SUM(G11:J11) -> 61128.21
A12: Oct | B12: =' 2011-2026'!$M$207 -> 0 | C12: =' 2011-2026'!N207 -> 0 | D12: =' 2011-2026'!O207 -> 0 | E12: =' 2011-2026'!P207 -> 0 | F12: =SUM(B12:E12) -> 0 | K12: =SUM(G12:J12) -> 0
A13: Nov | B13: =' 2011-2026'!$M$208 -> 0 | C13: =' 2011-2026'!N208 -> 0 | D13: =' 2011-2026'!O208 -> 0 | E13: =' 2011-2026'!P208 -> 0 | F13: =SUM(B13:E13) -> 0 | K13: =SUM(G13:J13) -> 0
A14: Dic | B14: =' 2011-2026'!$M$209 -> 0 | C14: =' 2011-2026'!N209 -> 0 | D14: =' 2011-2026'!O209 -> 0 | E14: =' 2011-2026'!P209 -> 0 | F14: =SUM(B14:E14) -> 0 | K14: =SUM(G14:J14) -> 0
B15: =SUM(B3:B14) -> 1144091.1 | C15: =SUM(C3:C14) -> 58230.19 | D15: =SUM(D3:D14) -> 233638.8 | E15: =SUM(E3:E14) -> 0 | F15: =SUM(F3:F14) -> 1435960.1 | G15: =SUM(G3:G14) -> 343079.5 | H15: =SUM(H3:H14) -> 30592.64 | I15: =SUM(I3:I14) -> 104973.81 | ... K15: =SUM(K3:K14) -> 722126.37
B18: =' 2011-2026'!M210 -> 1144091.1 | C18: =' 2011-2026'!N210 -> 58230.19 | D18: =' 2011-2026'!O210 -> 233638.8 | E18: =' 2011-2026'!P210 -> 0 | F18: =' 2011-2026'!L210 -> 1435960.1
B21: =B15-B18 -> 0 | C21: =C15-C18 -> 0 | D21: =D15-D18 -> 0 | E21: =E15-E18 -> 0 | F21: =F15-F18 -> 0
B25: Monto Fac | C25: =K15 -> 722126.37 | E25: 37
B26: Monto OC | C26: =F15 -> 1435960.1 | E26: =100-E25 -> 63
E27: =100-E26 -> 37
C49: % | D49: FACTURADO | E49: HH+ UTILIDAD | F49: HH+ UTIL TOTAL
B50: MINERIA | C50: 25.751614 | D50: 293801.3 | E50: 163521.3 | F50: =Objetivos!D2 -> 435908.24
B51: INDUSTRIA | C51: 41.493805 | D51: 30592.64 | E51: 25835.69 | F51: =Objetivos!D3 -> 27851.33
B52: PETROQUIMICA | C52: 37.844229 | D52: 104973.81 | E52: 19249.7 | F52: =Objetivos!D4 -> 183431.67
B53: S.MAQUINARIA | C53: 79.51285 | D53: 231630.41 | E53: 60053.29 | F53: =Objetivos!D5 -> 0
D54: =SUM(D50:D53) -> 660998.16 | E54: =SUM(E50:E53) -> 268659.98 | F54: =SUM(F50:F53) -> 647191.24
